Workbook
Name Slicer_Cohort: #N/A
Name Slicer_Gender: #N/A
Name Slicer_Institution_of_employment_at_registration: #N/A
Name Slicer_Institution_of_registration: #N/A

Sheet Dashboard
O1: Fellows status by institution of employment at registration
O2: Count of S.No. | P2: Status
O3: Institution of employment at registration | P3: In progress: Above 60 months | Q3: Completed:Delayed | R3: Completed:On time | S3: Grand Total
O4: AGINCOURT | Q4: 1 | S4: 1
O5: APHRC | Q5: 4 | S5: 4
O6: Ifakara Health Institute | P6: 1 | Q6: 6 | S6: 7
O7: Makerere University | P7: 2 | Q7: 13 | R7: 6 | S7: 21
O8: Moi University | P8: 6 | Q8: 8 | R8: 5 | S8: 19
O9: Obafemi Awolowo University | P9: 2 | Q9: 8 | R9: 21 | S9: 31
O10: University of Dar es Salaam | Q10: 2 | R10: 2 | S10: 4
O11: University of Ibadan | P11: 4 | Q11: 19 | R11: 13 | S11: 36
O12: University of Malawi | P12: 3 | Q12: 16 | R12: 8 | S12: 27
O13: University of Nairobi | P13: 3 | Q13: 12 | R13: 5 | S13: 20
O14: University of Rwanda | P14: 4 | Q14: 18 | R14: 2 | S14: 24
O15: University of the Witwatersrand | P15: 2 | Q15: 18 | R15: 6 | S15: 26
O16: Grand Total | P16: 27 | Q16: 125 | R16: 68 | S16: 220
O23: Fellows status by institution of registration
O24: Count of S.No. | P24: Status
O25: Institution of registration | P25: In progress: Above 60 months | Q25: Completed:Delayed | R25: Completed:On time | S25: Grand Total
O26: Makerere University | P26: 1 | Q26: 12 | R26: 5 | S26: 18
O27: Moi University | P27: 4 | Q27: 5 | R27: 2 | S27: 11
O28: Obafemi Awolowo University | Q28: 3 | R28: 17 | S28: 20
O29: University of Dar es Salaam | Q29: 4 | R29: 2 | S29: 6
O30: s | P30: 4 | Q30: 16 | R30: 12 | S30: 32
O31: University of Nairobi | P31: 5 | Q31: 14 | R31: 8 | S31: 27
O32: University of Rwanda | P32: 2 | Q32: 6 | S32: 8
O33: University of the Witwatersrand | P33: 9 | Q33: 56 | R33: 15 | S33: 80
O34: University of Malawi | P34: 2 | Q34: 9 | R34: 7 | S34: 18
O35: Grand Total | P35: 27 | Q35: 125 | R35: 68 | S35: 220
O40: Time to completion | Q40: No. of graduates
O41: Average in months | P41: =AVERAGE(Fellows!U2:U221) -> 60.271795 | Q41: =GETPIVOTDATA("S.No.",'By Cohort'!$A$27,"Current PhD Status (Completed/In Progress)","Completed") -> 195
O42: Average in yrs | P42: =P41/12 -> 5.0226496
O43: Std deviation in months | P43: =STDEV(Fellows!U2:U221) -> 19.919244
O44: median in months | P44: =MEDIAN(Fellows!U2:U221) -> 57 | Q44: max months to completion | R44: =MAX(Fellows!U2:U221) -> 139
O45: median in yrs | P45: =P44/12 -> 4.75 | Q45: min months to completion | R45: =MIN(Fellows!U2:U221) -> 22
Q47: Institution of employment at registration | R47: Number of fellows | S47: Average of Time to completion since enrolling CARTA (Months) | T47: StdDev of Time to completion since enrolling CARTA (Months) | U47: Max of Time to completion since enrolling CARTA (Months) | V47: Min of Time to completion since enrolling CARTA (Months)
Q48: AGINCOURT | R48: 1 | S48: 81 | T48: #DIV/0! | U48: 81 | V48: 81
Q49: APHRC | R49: 4 | S49: 66.5 | T49: 12.288206 | U49: 82 | V49: 52
Q50: Ifakara Health Institute | R50: 7 | S50: 70.333333 | T50: 17.037214 | U50: 99 | V50: 55
Q51: Makerere University | R51: 21 | S51: 63.105263 | T51: 18.961642 | U51: 107 | V51: 37
...

Sheet Sheet2

Sheet Sheet3
A1: Current PhD Status (Completed/In Progress) | B1: Completed
A3: Count of S.No.
A4: 193

Sheet Sheet1
A1: Status | B1: (Multiple Items)
B3: Column Labels
B4: Female | C4: Male | D4: Grand Total
A5: Count of S.No. | B5: 107 | C5: 86 | D5: 193

Sheet Sheet4
A3: Count of S.No. | B3: Column Labels
A4: Row Labels | B4: Completed | C4: In progress | D4: Grand Total
A5: AGINCOURT | B5: 1 | C5: 0 | D5: 1
A6: APHRC | B6: 1 | C6: 0 | D6: 1
A7: Ifakara Health Institute | B7: 0.85714286 | C7: 0.14285714 | D7: 1
A8: Makerere University | B8: 0.9047619 | C8: 0.095238095 | D8: 1
A9: Moi University | B9: 0.68421053 | C9: 0.31578947 | D9: 1
A10: Obafemi Awolowo University | B10: 0.93548387 | C10: 0.064516129 | D10: 1
A11: University of Dar es Salaam | B11: 1 | C11: 0 | D11: 1
A12: University of Ibadan | B12: 0.88888889 | C12: 0.11111111 | D12: 1
A13: University of Malawi | B13: 0.88888889 | C13: 0.11111111 | D13: 1
A14: University of Nairobi | B14: 0.85 | C14: 0.15 | D14: 1
A15: University of Rwanda | B15: 0.83333333 | C15: 0.16666667 | D15: 1
A16: University of the Witwatersrand | B16: 0.92307692 | C16: 0.076923077 | D16: 1
A17: Grand Total | B17: 0.87727273 | C17: 0.12272727 | D17: 1

Sheet Sheet6
A1: Status | B1: (Multiple Items)
A3: Institution of employment at registration | B3: Count of S.No.
A4: AGINCOURT | B4: 1
A5: APHRC | B5: 4
A6: Ifakara Health Institute | B6: 6
A7: Makerere University | B7: 19
A8: Moi University | B8: 13
A9: Obafemi Awolowo University | B9: 29
A10: University of Dar es Salaam | B10: 4
A11: University of Ibadan | B11: 32
A12: University of Malawi | B12: 24
A13: University of Nairobi | B13: 17
A14: University of Rwanda | B14: 20
A15: University of the Witwatersrand | B15: 24
A16: Grand Total | B16: 193

Sheet Sheet7

Sheet Fellows
A1: S.No. | B1: Unique ID | C1: First Name | D1: Middle Name | E1: Surname | F1: Gender | G1: Cohort | H1: Nationality | I1: Institution of employment at registration | J1: Institution of registration | K1: Date of PhD Registration | L1: Date of admission into CARTA | M1: Today | N1: In Progress: No. of months in the program | O1: Start date of LOA | P1: End of date of leave of Absence | Q1: No. of months | R1: No. of months since enrolment | S1: Date of completion (Defended/Graduated) | T1: Current PhD Status (Completed/In Progress) | U1: Time to completion since enrolling CARTA (Months) | V1: Status | W1: Time to completion since PhD registration (Months)
A2: 1 | B2: C6/020 | C2: Aanuoluwapo | D2: Omobolanle | E2: Olajubu | F2: Female | G2: 6 | H2: Nigeria | I2: Obafemi Awolowo University | J2: Obafemi Awolowo University | K2: 41908 | L2: 42430 | M2: =TODAY() -> 46037 | R2: =IF(N2="",U2,N2) -> 28 | S2: 43281 | T2: Completed | U2: =DATEDIF(L2,S2,"M")+1-Q2 -> 28 | V2: =IF(U2>51,"Completed:Delayed"," Completed:On time") -> Completed:On time | W2: =DATEDIF(K2,S2,"M")+1-Q2 -> 46
A3: 2 | B3: C9/015 | C3: Abiket | D3: Nanfizat | E3: Alamukii | F3: Female | G3: 9 | H3: Nigeria | I3: University of Ibadan | J3: University of Ibadan | K3: 42417 | L3: 43525 | M3: =TODAY() -> 46037 | R3: =IF(N3="",U3,N3) -> 54 | S3: 45163 | T3: Completed | U3: =DATEDIF(L3,S3,"M")+1-Q3 -> 54 | V3: =IF(U3>51,"Completed:Delayed"," Completed:On time") -> Completed:Delayed | W3: =DATEDIF(K3,S3,"M")+1-Q3 -> 91
A4: 3 | B4: C9/018 | C4: Abimbola | D4: Margaret | E4: Obimakinde | F4: Female | G4: 9 | H4: Nigeria | I4: University of Ibadan | J4: University of the Witwatersrand | K4: 43647 | L4: 43525 | M4: =TODAY() -> 46037 | R4: =IF(N4="",U4,N4) -> 58 | S4: 45280 | T4: Completed | U4: =DATEDIF(L4,S4,"M")+1-Q4 -> 58 | V4: =IF(U4>51,"Completed:Delayed"," Completed:On time") -> Completed:Delayed | W4: =DATEDIF(K4,S4,"M")+1-Q4 -> 54
A5: 4 | B5: C2/013 | C5: Abiodun | D5: Olufunke | E5: Oluwatoba | F5: Female | G5: 2 | H5: Nigeria | I5: University of Ibadan | J5: University of Ibadan | K5: 40920 | L5: 40969 | M5: =TODAY() -> 46037 | R5: =IF(N5="",U5,N5) -> 93 | S5: 43787 | T5: Completed | U5: =DATEDIF(L5,S5,"M")+1-Q5 -> 93 | V5: =IF(U5>51,"Completed:Delayed"," Completed:On time") -> Completed:Delayed | W5: =DATEDIF(K5,S5,"M")+1-Q5 -> 95
A6: 5 | B6: C7/003 | C6: Abiola | D6: Olubusola | E6: Komolafe | F6: Female | G6: 7 | H6: Nigeria | I6: Obafemi Awolowo University | J6: Obafemi Awolowo University | K6: 42458 | L6: 42795 | M6: =TODAY() -> 46037 | R6: =IF(N6="",U6,N6) -> 34 | S6: 43813 | T6: Completed | U6: =DATEDIF(L6,S6,"M")+1-Q6 -> 34 | V6: =IF(U6>51,"Completed:Delayed"," Completed:On time") -> Completed:On time | W6: =DATEDIF(K6,S6,"M")+1-Q6 -> 45
A7: 6 | B7: C2/001 | C7: Adebolajo | E7: Adeyemo | F7: Male | G7: 2 | H7: Nigeria | I7: University of Ibadan | J7: University of Ibadan | K7: 40924 | L7: 40969 | M7: =TODAY() -> 46037 | N7: =DATEDIF(L7,M7,"M") +1 -> 167 | R7: =IF(N7="",U7,N7) -> 167 | S7: 45183 | T7: Completed | U7: =DATEDIF(L7,S7,"M")+1-Q7 -> 139 | V7: =IF(U7>51,"Completed:Delayed"," Completed:On time") -> Completed:Delayed | W7: =DATEDIF(K7,S7,"M")+1-Q7 -> 140
A8: 7 | B8: C3/001 | C8: Adefolarin | D8: Olufolake | E8: Adeyinka | F8: Female | G8: 3 | H8: Nigeria | I8: University of Ibadan | J8: University of Ibadan | K8: 41325 | L8: 41334 | M8: =TODAY() -> 46037 | R8: =IF(N8="",U8,N8) -> 56 | S8: 43038 | T8: Completed | U8: =DATEDIF(L8,S8,"M")+1-Q8 -> 56 | V8: =IF(U8>51,"Completed:Delayed"," Completed:On time") -> Completed:Delayed | W8: =DATEDIF(K8,S8,"M")+1-Q8 -> 57
A9: 8 | B9: C8/002 | C9: Adeleye | D9: Abiodun | E9: Adeomi | F9: Male | G9: 8 | H9: Nigeria | I9: Obafemi Awolowo University | J9: University of the Witwatersrand | K9: 43318 | L9: 43160 | M9: =TODAY() -> 46037 | R9: =IF(N9="",U9,N9) -> 51 | S9: 44682 | T9: Completed | U9: =DATEDIF(L9,S9,"M")+1-Q9 -> 51 | V9: =IF(U9>51,"Completed:Delayed"," Completed:On time") -> Completed:On time | W9: =DATEDIF(K9,S9,"M")+1-Q9 -> 45
A10: 9 | B10: C2/007 | C10: Adeniyi | D10: Francis | E10: Fagbamigbe | F10: Male | G10: 2 | H10: Nigeria | I10: University of Ibadan | J10: University of Ibadan | K10: 40987 | L10: 40969 | M10: =TODAY() -> 46037 | R10: =IF(N10="",U10,N10) -> 25 | S10: 41729 | T10: Completed | U10: =DATEDIF(L10,S10,"M")+1-Q10 -> 25 | V10: =IF(U10>51,"Completed:Delayed"," Completed:On time") -> Completed:On time | W10: =DATEDIF(K10,S10,"M")+1-Q10 -> 25
A11: 10 | B11: C3/004 | C11: Adesola | D11: Oluwafunmilola | E11: Olumide | F11: Female | G11: 3 | H11: Nigeria | I11: University of Ibadan | J11: University of Ibadan | K11: 41326 | L11: 41334 | M11: =TODAY() -> 46037 | R11: =IF(N11="",U11,N11) -> 52 | S11: 42916 | T11: Completed | U11: =DATEDIF(L11,S11,"M")+1-Q11 -> 52 | V11: =IF(U11>51,"Completed:Delayed"," Completed:On time") -> Completed:Delayed | W11: =DATEDIF(K11,S11,"M")+1-Q11 -> 53
A12: 11 | B12: C4/002 | C12: Admire | D12: Takuranhamo | E12: Chikandiwa | F12: Male | G12: 4 | H12: South Africa | I12: University of the Witwatersrand | J12: University of the Witwatersrand | K12: 42809 | L12: 41699 | M12: =TODAY() -> 46037 | R12: =IF(N12="",U12,N12) -> 69 | S12: 43799 | T12: Completed | U12: =DATEDIF(L12,S12,"M")+1-Q12 -> 69 | V12: =IF(U12>51,"Completed:Delayed"," Completed:On time") -> Completed:Delayed | W12: =DATEDIF(K12,S12,"M")+1-Q12 -> 33
A13: 12 | B13: C9/021 | C13: Alex | D13: John | E13: Ntamatungiro | F13: Male | G13: 9 | H13: Tanzania | I13: Ifakara Health Institute | J13: University of the Witwatersrand | K13: 43861 | L13: 43525 | M13: =TODAY() -> 46037 | R13: =IF(N13="",U13,N13) -> 59 | S13: 45313 | T13: Completed | U13: =DATEDIF(L13,S13,"M")+1-Q13 -> 59 | V13: =IF(U13>51,"Completed:Delayed"," Completed:On time") -> Completed:Delayed | W13: =DATEDIF(K13,S13,"M")+1-Q13 -> 48
A14: 13 | B14: C7/002 | C14: Alexander | D14: - | E14: Kagaha | F14: Male | G14: 7 | H14: Uganda | I14: Makerere University | J14: University of the Witwatersrand | K14: 42889 | L14: 42795 | M14: =TODAY() -> 46037 | R14: =IF(N14="",U14,N14) -> 51 | S14: 44334 | T14: Completed | U14: =DATEDIF(L14,S14,"M")+1-Q14 -> 51 | V14: =IF(U14>51,"Completed:Delayed"," Completed:On time") -> Completed:On time | W14: =DATEDIF(K14,S14,"M")+1-Q14 -> 48
A15: 14 | B15: C10/001 | C15: Alice | E15: Muhayimana | F15: Female | G15: 10 | H15: Rwanda | I15: University of Rwanda | J15: University of the Witwatersrand | K15: 43861 | L15: 43891 | M15: =TODAY() -> 46037 | N15: =DATEDIF(L15,M15,"M") +1 -> 71 | R15: =IF(N15="",U15,N15) -> 71 | S15: 45538 | T15: Completed | U15: =DATEDIF(L15,S15,"M")+1-Q15 -> 55 | V15: =IF(U15>51,"Completed:Delayed"," Completed:On time") -> Completed:Delayed | W15: =DATEDIF(K15,S15,"M")+1-Q15 -> 56
A16: 15 | B16: C2/002 | C16: Alinane Linda | E16: Nyondo-Mipando | F16: Female | G16: 2 | H16: Malawi | I16: University of Malawi | J16: University of Malawi | K16: 40917 | L16: 40969 | M16: =TODAY() -> 46037 | R16: =IF(N16="",U16,N16) -> 49 | S16: 42460 | T16: Completed | U16: =DATEDIF(L16,S16,"M")+1-Q16 -> 49 | V16: =IF(U16>51,"Completed:Delayed"," Completed:On time") -> Completed:On time | W16: =DATEDIF(K16,S16,"M")+1-Q16 -> 51
A17: 16 | B17: C4/003 | C17: Andrew | D17: - | E17: Tamale | F17: Male | G17: 4 | H17: Uganda | I17: Makerere University | J17: Makerere University | K17: 41710 | L17: 41699 | M17: =TODAY() -> 46037 | R17: =IF(N17="",U17,N17) -> 37 | S17: 42824 | T17: Completed | U17: =DATEDIF(L17,S17,"M")+1-Q17 -> 37 | V17: =IF(U17>51,"Completed:Delayed"," Completed:On time") -> Completed:On time | W17: =DATEDIF(K17,S17,"M")+1-Q17 -> 37
A18: 17 | B18: C3/002 | C18: Angeline | E18: Chepchirchir | F18: Female | G18: 3 | H18: Kenya | I18: University of Nairobi | J18: University of Nairobi | K18: 41329 | L18: 41334 | M18: =TODAY() -> 46037 | R18: =IF(N18="",U18,N18) -> 82 | S18: 43819 | T18: Completed | U18: =DATEDIF(L18,S18,"M")+1-Q18 -> 82 | V18: =IF(U18>51,"Completed:Delayed"," Completed:On time") -> Completed:Delayed | W18: =DATEDIF(K18,S18,"M")+1-Q18 -> 82
A19: 18 | B19: C3/020 | C19: Anitha | D19: - | E19: Philbert | F19: Female | G19: 3 | H19: Tanzania | I19: University of Dar es Salaam | J19: University of Dar es Salaam | K19: 41205 | L19: 41334 | M19: =TODAY() -> 46037 | R19: =IF(N19="",U19,N19) -> 42 | S19: 42612 | T19: Completed | U19: =DATEDIF(L19,S19,"M")+1-Q19 -> 42 | V19: =IF(U19>51,"Completed:Delayed"," Completed:On time") -> Completed:On time | W19: =DATEDIF(K19,S19,"M")+1-Q19 -> 47
A20: 19 | B20: C3/003 | C20: Anne | D20: Majuma | E20: Khisa | F20: Female | G20: 3 | H20: Kenya | I20: University of Nairobi | J20: University of Nairobi | K20: 41097 | L20: 41334 | M20: =TODAY() -> 46037 | R20: =IF(N20="",U20,N20) -> 46 | S20: 42735 | T20: Completed | U20: =DATEDIF(L20,S20,"M")+1-Q20 -> 46 | V20: =IF(U20>51,"Completed:Delayed"," Completed:On time") -> Completed:On time | W20: =DATEDIF(K20,S20,"M")+1-Q20 -> 54
A21: 20 | B21: C8/014 | C21: Atupele | D21: Ngina | E21: Mulaga | F21: Female | G21: 8 | H21: Malawi | I21: University of Malawi | J21: University of Malawi | K21: 43191 | L21: 43160 | M21: =TODAY() -> 46037 | R21: =IF(N21="",U21,N21) -> 58 | S21: 44900 | T21: Completed | U21: =DATEDIF(L21,S21,"M")+1-Q21 -> 58 | V21: =IF(U21>51,"Completed:Delayed"," Completed:On time") -> Completed:Delayed | W21: =DATEDIF(K21,S21,"M")+1-Q21 -> 57
A22: 21 | B22: C2/003 | C22: Austin | D22: Henderson | E22: Mtethiwa | F22: Male | G22: 2 | H22: Malawi | I22: University of Malawi | J22: University of Malawi | K22: 40977 | L22: 40969 | M22: =TODAY() -> 46037 | R22: =IF(N22="",U22,N22) -> 57 | S22: 42704 | T22: Completed | U22: =DATEDIF(L22,S22,"M")+1-Q22 -> 57 | V22: =IF(U22>51,"Completed:Delayed"," Completed:On time") -> Completed:Delayed | W22: =DATEDIF(K22,S22,"M")+1-Q22 -> 57
A23: 22 | B23: C4/001 | C23: Ayodele | D23: John | E23: Alonge | F23: Male | G23: 4 | H23: Nigeria | I23: University of Ibadan | J23: University of Nairobi | K23: 42277 | L23: 41699 | M23: =TODAY() -> 46037 | R23: =IF(N23="",U23,N23) -> 46 | S23: 43089 | T23: Completed | U23: =DATEDIF(L23,S23,"M")+1-Q23 -> 46 | V23: =IF(U23>51,"Completed:Delayed"," Completed:On time") -> Completed:On time | W23: =DATEDIF(K23,S23,"M")+1-Q23 -> 27
A24: 23 | B24: C1/001 | C24: Babatunde | D24: Olubayo | E24: Adedokun | F24: Male | G24: 1 | H24: Nigeria | I24: University of Ibadan | J24: University of Ibadan | K24: 40603 | L24: 40634 | M24: =TODAY() -> 46037 | R24: =IF(N24="",U24,N24) -> 70 | S24: 42766 | T24: Completed | U24: =DATEDIF(L24,S24,"M")+1-Q24 -> 70 | V24: =IF(U24>51,"Completed:Delayed"," Completed:On time") -> Completed:Delayed | W24: =DATEDIF(K24,S24,"M")+1-Q24 -> 71 | X24: Key
A25: 24 | B25: C6/001 | C25: Beatrice | D25: Waitherero | E25: Maina | F25: Female | G25: 6 | H25: Kenya | I25: APHRC | J25: University of the Witwatersrand | K25: 42816 | L25: 42430 | M25: =TODAY() -> 46037 | R25: =IF(N25="",U25,N25) -> 67 | S25: 44461 | T25: Completed | U25: =DATEDIF(L25,S25,"M")+1-Q25 -> 67 | V25: =IF(U25>51,"Completed:Delayed"," Completed:On time") -> Completed:Delayed | W25: =DATEDIF(K25,S25,"M")+1-Q25 -> 55
A26: 25 | B26: C10/006 | C26: Beryl | D26: Chelangat | E26: Maritim | F26: Female | G26: 10 | H26: Kenya | I26: Moi University | J26: University of the Witwatersrand | K26: 44013 | L26: 43891 | M26: =TODAY() -> 46037 | R26: =IF(N26="",U26,N26) -> 43 | S26: 45188 | T26: Completed | U26: =DATEDIF(L26,S26,"M")+1-Q26 -> 43 | V26: =IF(U26>51,"Completed:Delayed"," Completed:On time") -> Completed:On time | W26: =DATEDIF(K26,S26,"M")+1-Q26 -> 39
A27: 26 | B27: C6/002 | C27: Betty | D27: Karimi | E27: Mwiti | F27: Female | G27: 6 | H27: Kenya | I27: University of Nairobi | J27: University of Nairobi | K27: 42704 | L27: 42430 | M27: =TODAY() -> 46037 | O27: 43941 | P27: 43993 | Q27: 2 | R27: =IF(N27="",U27,N27) -> 52 | S27: 44069 | T27: Completed | U27: =DATEDIF(L27,S27,"M")+1-Q27 -> 52 | V27: =IF(U27>51,"Completed:Delayed"," Completed:On time") -> Completed:Delayed | W27: =DATEDIF(K27,S27,"M")+1-Q27 -> 43
A28: 27 | B28: C7/004 | C28: Blessings | D28: Nyasilia Kaunda | E28: Kaunda-Khangamwa | F28: Female | G28: 7 | H28: Malawi | I28: University of Malawi | J28: University of the Witwatersrand | K28: 42855 | L28: 42795 | M28: =TODAY() -> 46037 | R28: =IF(N28="",U28,N28) -> 51 | S28: 44334 | T28: Completed | U28: =DATEDIF(L28,S28,"M")+1-Q28 -> 51 | V28: =IF(U28>51,"Completed:Delayed"," Completed:On time") -> Completed:On time | W28: =DATEDIF(K28,S28,"M")+1-Q28 -> 49
A29: 28 | B29: C4/004 | C29: Boladale | D29: Moyosore | E29: Mapayi | F29: Female | G29: 4 | H29: Nigeria | I29: Obafemi Awolowo University | J29: Obafemi Awolowo University | K29: 41348 | L29: 41699 | M29: =TODAY() -> 46037 | R29: =IF(N29="",U29,N29) -> 37 | S29: 42825 | T29: Completed | U29: =DATEDIF(L29,S29,"M")+1-Q29 -> 37 | V29: =IF(U29>51,"Completed:Delayed"," Completed:On time") -> Completed:On time | W29: =DATEDIF(K29,S29,"M")+1-Q29 -> 49
A30: 29 | B30: C2/008 | C30: Tumwine | E30: Gabriel | F30: Male | G30: 2 | H30: Uganda | I30: Makerere University | J30: Makerere University | K30: 40933 | L30: 40969 | M30: =TODAY() -> 46037 | N30: =DATEDIF(L30,M30,"M") +1 -> 167 | R30: =IF(N30="",U30,N30) -> 167 | T30: In progress | U30: =IF(N30>60,"In progress: Above 60 months","In progress: Below 60 Months") -> In progress: Above 60 months | V30: =IF(N30>60,"In progress: Above 60 months","In progress: Below 60 Months") -> In progress: Above 60 months
A31: 30 | B31: C4/005 | C31: Bolutife | D31: Ayokunnu | E31: Olusanya | F31: Male | G31: 4 | H31: Nigeria | I31: University of Ibadan | J31: University of Ibadan | K31: 41830 | L31: 41699 | M31: =TODAY() -> 46037 | R31: =IF(N31="",U31,N31) -> 85 | S31: 44260 | T31: Completed | U31: =DATEDIF(L31,S31,"M")+1-Q31 -> 85 | V31: =IF(U31>51,"Completed:Delayed"," Completed:On time") -> Completed:Delayed | W31: =DATEDIF(K31,S31,"M")+1-Q31 -> 80
A32: 31 | B32: C1/003 | C32: Caroline | D32: Sultan | E32: Sambai | F32: Female | G32: 1 | H32: Kenya | I32: Moi University | J32: Moi University | K32: 40827 | L32: 40634 | M32: =TODAY() -> 46037 | R32: =IF(N32="",U32,N32) -> 36 | S32: 41729 | T32: Completed | U32: =DATEDIF(L32,S32,"M")+1-Q32 -> 36 | V32: =IF(U32>51,"Completed:Delayed"," Completed:On time") -> Completed:On time | W32: =DATEDIF(K32,S32,"M")+1-Q32 -> 30 | Y32: Completed below 60 months
A33: 32 | B33: C4/007 | C33: Caroline | D33: Jepkoech | E33: Sawe | F33: Female | G33: 4 | H33: Kenya | I33: Moi University | J33: University of Nairobi | K33: 41730 | L33: 41699 | M33: =TODAY() -> 46037 | R33: =IF(N33="",U33,N33) -> 91 | S33: 44442 | T33: Completed | U33: =DATEDIF(L33,S33,"M")+1-Q33 -> 91 | V33: =IF(U33>51,"Completed:Delayed"," Completed:On time") -> Completed:Delayed | W33: =DATEDIF(K33,S33,"M")+1-Q33 -> 90
A34: 33 | B34: C7/006 | C34: Catherine | D34: Mawia | E34: Musyoka | F34: Female | G34: 7 | H34: Kenya | I34: University of Nairobi | J34: University of Nairobi | K34: 42916 | L34: 42795 | M34: =TODAY() -> 46037 | R34: =IF(N34="",U34,N34) -> 55 | S34: 44468 | T34: Completed | U34: =DATEDIF(L34,S34,"M")+1-Q34 -> 55 | V34: =IF(U34>51,"Completed:Delayed"," Completed:On time") -> Completed:Delayed | W34: =DATEDIF(K34,S34,"M")+1-Q34 -> 51
A35: 34 | B35: C5/002 | C35: Celestin | E35: Ndikumana | F35: Male | G35: 5 | H35: Rwanda | I35: University of Rwanda | J35: Moi University | K35: 42993 | L35: 42064 | M35: =TODAY() -> 46037 | R35: =IF(N35="",U35,N35) -> 58 | S35: 43830 | T35: Completed | U35: =DATEDIF(L35,S35,"M")+1-Q35 -> 58 | V35: =IF(U35>51,"Completed:Delayed"," Completed:On time") -> Completed:Delayed | W35: =DATEDIF(K35,S35,"M")+1-Q35 -> 28
A36: 35 | B36: C7/005 | C36: Celestin | E36: Banamwana | F36: Male | G36: 7 | H36: Rwanda | I36: University of Rwanda | J36: Makerere University | K36: 42855 | L36: 42795 | M36: =TODAY() -> 46037 | R36: =IF(N36="",U36,N36) -> 82 | S36: 45273 | T36: Completed | U36: =DATEDIF(L36,S36,"M")+1-Q36 -> 82 | V36: =IF(U36>51,"Completed:Delayed"," Completed:On time") -> Completed:Delayed | W36: =DATEDIF(K36,S36,"M")+1-Q36 -> 80
A37: 36 | B37: C1/002 | C37: Celine | E37: Niwemahoro | F37: Female | G37: 1 | H37: Rwanda | I37: University of Rwanda | J37: University of Dar es Salaam | K37: 40616 | L37: 40634 | M37: =TODAY() -> 46037 | R37: =IF(N37="",U37,N37) -> 79 | S37: 43023 | T37: Completed | U37: =DATEDIF(L37,S37,"M")+1-Q37 -> 79 | V37: =IF(U37>51,"Completed:Delayed"," Completed:On time") -> Completed:Delayed | W37: =DATEDIF(K37,S37,"M")+1-Q37 -> 80 | Y37: Completed within 51 months
A38: 37 | B38: C3/006 | C38: Charles | D38: Masulani | E38: Mwale | F38: Male | G38: 3 | H38: Rwanda | I38: University of Rwanda | J38: University of Rwanda | K38: 41200 | L38: 41334 | M38: =TODAY() -> 46037 | R38: =IF(N38="",U38,N38) -> 57 | S38: 43069 | T38: Completed | U38: =DATEDIF(L38,S38,"M")+1-Q38 -> 57 | V38: =IF(U38>51,"Completed:Delayed"," Completed:On time") -> Completed:Delayed | W38: =DATEDIF(K38,S38,"M")+1-Q38 -> 62
A39: 38 | B39: C9/008 | C39: Charles | E39: Ssemugabo | F39: Male | G39: 9 | H39: Uganda | I39: Makerere University | J39: Makerere University | K39: 43647 | L39: 43525 | M39: =TODAY() -> 46037 | R39: =IF(N39="",U39,N39) -> 55 | S39: 45174 | T39: Completed | U39: =DATEDIF(L39,S39,"M")+1-Q39 -> 55 | V39: =IF(U39>51,"Completed:Delayed"," Completed:On time") -> Completed:Delayed | W39: =DATEDIF(K39,S39,"M")+1-Q39 -> 51
A40: 39 | B40: C5/001 | C40: Cheikh Mbacké | E40: Faye | F40: Male | G40: 5 | H40: Senegal | I40: APHRC | J40: University of the Witwatersrand | K40: 42370 | L40: 42064 | M40: =TODAY() -> 46037 | R40: =IF(N40="",U40,N40) -> 52 | S40: 43646 | T40: Completed | U40: =DATEDIF(L40,S40,"M")+1-Q40 -> 52 | V40: =IF(U40>51,"Completed:Delayed"," Completed:On time") -> Completed:Delayed | W40: =DATEDIF(K40,S40,"M")+1-Q40 -> 42
...

Sheet Status
A1: Current PhD Status (Completed/In Progress) | B1: Completed
A3: Count of S.No. | B3: Cohort
A4: Status | B4: 1 | C4: 2 | D4: 3 | E4: 4 | F4: 5 | G4: 6 | H4: 7 | I4: 8 | J4: 9 | K4: 10 | L4: Grand Total
A5: Completed:On time | B5: 6 | C5: 6 | D5: 10 | E5: 6 | F5: 3 | G5: 12 | H5: 11 | I5: 6 | J5: 3 | K5: 5 | L5: 68
A6: Completed:Delayed | B6: 14 | C6: 9 | D6: 8 | E6: 19 | F6: 15 | G6: 12 | H6: 13 | I6: 11 | J6: 13 | K6: 11 | L6: 125
A7: Grand Total | B7: 20 | C7: 15 | D7: 18 | E7: 25 | F7: 18 | G7: 24 | H7: 24 | I7: 17 | J7: 16 | K7: 16 | L7: 193

Sheet By Cohort
A3: Count of S.No. | B3: Status | H3: Count of S.No. | I3: Gender
A4: Cohort | B4: Completed:On time | C4: Completed:Delayed | D4: In progress: Above 60 months | E4: In progress: Below 60 Months | F4: Grand Total | H4: Status | I4: Female | J4: Male | K4: Grand Total
A5: 1 | B5: 6 | C5: 14 | F5: 20 | H5: Completed:On time | I5: 38 | J5: 30 | K5: 68
A6: 2 | B6: 6 | C6: 9 | D6: 1 | F6: 16 | H6: Completed:Delayed | I6: 69 | J6: 56 | K6: 125
A7: 3 | B7: 10 | C7: 8 | D7: 3 | F7: 21 | H7: In progress: Above 60 months | I7: 17 | J7: 10 | K7: 27
A8: 4 | B8: 6 | C8: 19 | D8: 1 | F8: 26 | H8: Grand Total | I8: 124 | J8: 96 | K8: 220
A9: 5 | B9: 3 | C9: 15 | D9: 2 | F9: 20
A10: 6 | B10: 12 | C10: 12 | F10: 24
A11: 7 | B11: 11 | C11: 13 | F11: 24
A12: 8 | B12: 6 | C12: 11 | D12: 6 | F12: 23
A13: 9 | B13: 3 | C13: 13 | D13: 6 | F13: 22
A14: 10 | B14: 5 | C14: 13 | D14: 6 | F14: 24
A15: 11 | E15: 20 | F15: 20
A16: Grand Total | B16: 68 | C16: 127 | D16: 25 | E16: 20 | F16: 240
A27: Count of S.No. | B27: Current PhD Status (Completed/In Progress)
A28: Cohort | B28: Completed | C28: In progress | D28: Grand Total
A29: 1 | B29: 20 | D29: 20
A30: 2 | B30: 15 | C30: 1 | D30: 16
A31: 3 | B31: 18 | C31: 3 | D31: 21
A32: 4 | B32: 25 | C32: 1 | D32: 26
A33: 5 | B33: 18 | C33: 2 | D33: 20
A34: 6 | B34: 24 | D34: 24
A35: 7 | B35: 24 | D35: 24
A36: 8 | B36: 17 | C36: 6 | D36: 23
A37: 9 | B37: 16 | C37: 6 | D37: 22
A38: 10 | B38: 18 | C38: 6 | D38: 24
A39: 11 | C39: 20 | D39: 20
A40: Grand Total | B40: 195 | C40: 45 | D40: 240
A68: Date of completion (Defended/Graduated) | B68: (All)
A69: Status | B69: (All)
A71: Count of S.No. | B71: Gender
A72: Cohort | B72: Female | C72: Male | D72: Grand Total
A73: 1 | B73: 7 | C73: 13 | D73: 20
A74: 2 | B74: 7 | C74: 9 | D74: 16
A75: 3 | B75: 12 | C75: 9 | D75: 21
A76: 4 | B76: 12 | C76: 14 | D76: 26
A77: 5 | B77: 11 | C77: 9 | D77: 20
A78: 6 | B78: 15 | C78: 9 | D78: 24
A79: 7 | B79: 18 | C79: 6 | D79: 24
A80: 8 | B80: 14 | C80: 9 | D80: 23
...

Sheet By year
A4: Current PhD Status (Completed/In Progress) | B4: (All)
A6: Count of S.No. | B6: Gender
A7: Date of completion (Defended/Graduated) | B7: Female | C7: Male | D7: Grand Total
A8: (blank) | B8: 26 | C8: 19 | D8: 45
A9: 2013 | B9: 1 | C9: 2 | D9: 3
A10: 2014 | B10: 2 | C10: 3 | D10: 5
A11: 2015 | B11: 2 | C11: 6 | D11: 8
A12: 2016 | B12: 7 | C12: 9 | D12: 16
A13: 2017 | B13: 8 | C13: 7 | D13: 15
A14: 2018 | B14: 7 | C14: 9 | D14: 16
A15: 2019 | B15: 13 | C15: 11 | D15: 24
A16: 2020 | B16: 6 | C16: 4 | D16: 10
A17: 2021 | B17: 20 | C17: 10 | D17: 30
A18: 2022 | B18: 11 | C18: 3 | D18: 14
A19: 2023 | B19: 13 | C19: 9 | D19: 22
... A22: Grand Total | B22: 135 | C22: 105 | D22: 240

Sheet Institution of employment
A2: Status | B2: (All)
J3: Current PhD Status (Completed/In Progress) | K3: (All)
B4: Current PhD Status (Completed/In Progress) | C4: Values
B5: Completed | D5: In progress | F5: Total No. | G5: Total % | K5: Status | L5: Values
A6: Institution of employment at registration | B6: No. | C6: % | D6: No. | E6: % | K6: In progress: Above 60 months | M6: In progress: Below 60 Months | O6: Completed:Delayed | Q6: Completed:On time | S6: Total No. | T6: Total %
A7: AGINCOURT | B7: 1 | C7: 0.5 | D7: 1 | E7: 0.5 | F7: 2 | G7: 1 | J7: Institution of employment at registration | K7: No. | L7: % | M7: No. | N7: % | O7: No. | P7: % | Q7: No. | R7: %
A8: APHRC | B8: 4 | C8: 1 | E8: 0 | F8: 4 | G8: 1 | J8: AGINCOURT | L8: 0 | M8: 1 | N8: 0.5 | O8: 1 | P8: 0.5 | R8: 0 | S8: 2 | T8: 1
A9: Ifakara Health Institute | B9: 7 | C9: 0.875 | D9: 1 | E9: 0.125 | F9: 8 | G9: 1 | J9: APHRC | L9: 0 | N9: 0 | O9: 4 | P9: 1 | R9: 0 | S9: 4 | T9: 1
A10: Makerere University | B10: 19 | C10: 0.82608696 | D10: 4 | E10: 0.17391304 | F10: 23 | G10: 1 | J10: Ifakara Health Institute | L10: 0 | M10: 1 | N10: 0.125 | O10: 7 | P10: 0.875 | R10: 0 | S10: 8 | T10: 1
A11: Moi University | B11: 13 | C11: 0.65 | D11: 7 | E11: 0.35 | F11: 20 | G11: 1 | J11: Makerere University | K11: 2 | L11: 0.086956522 | M11: 2 | N11: 0.086956522 | O11: 13 | P11: 0.56521739 | Q11: 6 | R11: 0.26086957 | S11: 23 | T11: 1
A12: Obafemi Awolowo University | B12: 29 | C12: 0.87878788 | D12: 4 | E12: 0.12121212 | F12: 33 | G12: 1 | J12: Moi University | K12: 6 | L12: 0.3 | M12: 1 | N12: 0.05 | O12: 8 | P12: 0.4 | Q12: 5 | R12: 0.25 | S12: 20 | T12: 1
A13: University of Dar es Salaam | B13: 4 | C13: 1 | E13: 0 | F13: 4 | G13: 1 | J13: Obafemi Awolowo University | K13: 2 | L13: 0.060606061 | M13: 2 | N13: 0.060606061 | O13: 8 | P13: 0.24242424 | Q13: 21 | R13: 0.63636364 | S13: 33 | T13: 1
A14: University of Ibadan | B14: 32 | C14: 0.82051282 | D14: 7 | E14: 0.17948718 | F14: 39 | G14: 1 | J14: University of Dar es Salaam | L14: 0 | N14: 0 | O14: 2 | P14: 0.5 | Q14: 2 | R14: 0.5 | S14: 4 | T14: 1
A15: University of Malawi | B15: 24 | C15: 0.8 | D15: 6 | E15: 0.2 | F15: 30 | G15: 1 | J15: University of Ibadan | K15: 4 | L15: 0.1025641 | M15: 3 | N15: 0.076923077 | O15: 19 | P15: 0.48717949 | Q15: 13 | R15: 0.33333333 | S15: 39 | T15: 1
A16: University of Nairobi | B16: 17 | C16: 0.73913043 | D16: 6 | E16: 0.26086957 | F16: 23 | G16: 1 | J16: University of Malawi | K16: 3 | L16: 0.1 | M16: 3 | N16: 0.1 | O16: 16 | P16: 0.53333333 | Q16: 8 | R16: 0.26666667 | S16: 30 | T16: 1
A17: University of Rwanda | B17: 20 | C17: 0.76923077 | D17: 6 | E17: 0.23076923 | F17: 26 | G17: 1 | J17: University of Nairobi | K17: 3 | L17: 0.13043478 | M17: 3 | N17: 0.13043478 | O17: 12 | P17: 0.52173913 | Q17: 5 | R17: 0.2173913 | S17: 23 | T17: 1
A18: University of the Witwatersrand | B18: 25 | C18: 0.96153846 | D18: 1 | E18: 0.038461538 | F18: 26 | G18: 1 | J18: University of Rwanda | K18: 4 | L18: 0.15384615 | M18: 2 | N18: 0.076923077 | O18: 18 | P18: 0.69230769 | Q18: 2 | R18: 0.076923077 | S18: 26 | T18: 1
A19: Somali National University | C19: 0 | D19: 2 | E19: 1 | F19: 2 | G19: 1 | J19: University of the Witwatersrand | K19: 1 | L19: 0.038461538 | N19: 0 | O19: 19 | P19: 0.73076923 | Q19: 6 | R19: 0.23076923 | S19: 26 | T19: 1
A20: Grand Total | B20: 195 | C20: 0.8125 | D20: 45 | E20: 0.1875 | F20: 240 | G20: 1 | J20: Somali National University | L20: 0 | M20: 2 | N20: 1 | P20: 0 | R20: 0 | S20: 2 | T20: 1
J21: Grand Total | K21: 25 | L21: 0.10416667 | M21: 20 | N21: 0.083333333 | O21: 127 | P21: 0.52916667 | Q21: 68 | R21: 0.28333333 | S21: 240 | T21: 1
A23: Status | B23: (Multiple Items)
A25: No. | B25: Gender
A26: Institution of employment at registration | B26: Female | C26: Male | D26: Grand Total
A27: AGINCOURT | C27: 1 | D27: 1 | J27: Count of S.No. | K27: Status
A28: APHRC | B28: 1 | C28: 3 | D28: 4 | J28: Institution of employment at registration | K28: In progress: Above 60 months | L28: In progress: Below 60 Months | M28: Completed:Delayed | N28: Completed:On time | O28: Grand Total
A29: Ifakara Health Institute | B29: 5 | C29: 2 | D29: 7 | J29: AGINCOURT | L29: 1 | M29: 1 | O29: 2
A30: Makerere University | B30: 6 | C30: 13 | D30: 19 | J30: APHRC | M30: 4 | O30: 4
A31: Moi University | B31: 11 | C31: 2 | D31: 13 | J31: Ifakara Health Institute | L31: 1 | M31: 7 | O31: 8
A32: Obafemi Awolowo University | B32: 15 | C32: 14 | D32: 29 | J32: Makerere University | K32: 2 | L32: 2 | M32: 13 | N32: 6 | O32: 23
A33: University of Dar es Salaam | B33: 2 | C33: 2 | D33: 4 | J33: Moi University | K33: 6 | L33: 1 | M33: 8 | N33: 5 | O33: 20
A34: University of Ibadan | B34: 18 | C34: 14 | D34: 32 | J34: Obafemi Awolowo University | K34: 2 | L34: 2 | M34: 8 | N34: 21 | O34: 33
A35: University of Malawi | B35: 9 | C35: 15 | D35: 24 | J35: University of Dar es Salaam | M35: 2 | N35: 2 | O35: 4
A36: University of Nairobi | B36: 14 | C36: 3 | D36: 17 | J36: University of Ibadan | K36: 4 | L36: 3 | M36: 19 | N36: 13 | O36: 39
A37: University of Rwanda | B37: 10 | C37: 10 | D37: 20 | J37: University of Malawi | K37: 3 | L37: 3 | M37: 16 | N37: 8 | O37: 30
A38: University of the Witwatersrand | B38: 18 | C38: 7 | D38: 25 | J38: University of Nairobi | K38: 3 | L38: 3 | M38: 12 | N38: 5 | O38: 23
A39: Grand Total | B39: 109 | C39: 86 | D39: 195 | J39: University of Rwanda | K39: 4 | L39: 2 | M39: 18 | N39: 2 | O39: 26
J40: University of the Witwatersrand | K40: 1 | M40: 19 | N40: 6 | O40: 26
J41: Somali National University | L41: 2 | O41: 2
J42: Grand Total | K42: 25 | L42: 20 | M42: 127 | N42: 68 | O42: 240

Sheet Av time to completion
A3: Institution of employment at registration | B3: No. of fellows (Months) | C3: Average of Time to completion since enrolling CARTA (Months) | D3: StdDev of Time to completion since enrolling CARTA (Months) | E3: Max of Time to completion since enrolling CARTA (Months) | F3: Min of Time to completion since enrolling CARTA (Months) | G3: Median time to completion
A4: AGINCOURT | B4: 1 | C4: 81 | D4: #DIV/0! | E4: 81 | F4: 81
A5: APHRC | B5: 4 | C5: 66.5 | D5: 12.288206 | E5: 82 | F5: 52
A6: Ifakara Health Institute | B6: 7 | C6: 70.333333 | D6: 17.037214 | E6: 99 | F6: 55
A7: Makerere University | B7: 21 | C7: 63.105263 | D7: 18.961642 | E7: 107 | F7: 37
A8: Moi University | B8: 19 | C8: 61.846154 | D8: 19.527101 | E8: 101 | F8: 36
A9: Obafemi Awolowo University | B9: 31 | C9: 42.310345 | D9: 12.015179 | E9: 66 | F9: 24
A10: University of Dar es Salaam | B10: 4 | C10: 51.75 | D10: 7.410578 | E10: 58 | F10: 42
A11: University of Ibadan | B11: 36 | C11: 60.40625 | D11: 23.305626 | E11: 139 | F11: 22
A12: University of Malawi | B12: 27 | C12: 63.458333 | D12: 21.149528 | E12: 114 | F12: 28
A13: University of Nairobi | B13: 20 | C13: 62.823529 | D13: 21.307966 | E13: 115 | F13: 33
A14: University of Rwanda | B14: 24 | C14: 66.85 | D14: 14.113357 | E14: 104 | F14: 50
A15: University of the Witwatersrand | B15: 26 | C15: 64.625 | D15: 19.602157 | E15: 101 | F15: 32
A16: Grand Total | B16: 220 | C16: 60.196891 | D16: 20.00892 | E16: 139 | F16: 22
A33: Cohort | B33: Average of Time to completion since enrolling CARTA (Months) | C33: StdDev of Time to completion since enrolling CARTA (Months)
A34: 1 | B34: 59.6 | C34: 21.731374
A35: 2 | B35: 59.933333 | C35: 28.763734
A36: 3 | B36: 52.666667 | C36: 19.769257
A37: 4 | B37: 69.36 | C37: 23.44298
A38: 5 | B38: 61.444444 | C38: 13.975703
A39: 6 | B39: 61.875 | C39: 24.726878
A40: 7 | B40: 59.458333 | C40: 18.218431
A41: 8 | B41: 61.470588 | C41: 16.591103
A42: 9 | B42: 57.8125 | C42: 7.8419279
A43: 10 | B43: 53.5625 | C43: 11.764176
A44: Grand Total | B44: 60.196891 | C44: 20.00892
A52: Cohort | B52: Average of Time to completion since enrolling CARTA (Months) | C52: StdDev of Time to completion since enrolling CARTA (Months)
A53: 1 | B53: 59.6 | C53: 21.731374
A54: 2 | B54: 59.933333 | C54: 28.763734
A55: 3 | B55: 52.666667 | C55: 19.769257
A56: 4 | B56: 69.36 | C56: 23.44298
A57: 5 | B57: 62.388889 | C57: 14.568858
A58: 6 | B58: 56.285714 | C58: 18.281529
A59: 7 | B59: 57.454545 | C59: 14.268604
A60: 8 | B60: 51.818182 | C60: 11.320938
A61: 9 | B61: 56 | C61: 5.4619899
A62: 10 | B62: 39.8 | C62: 9.9849887
A63: Grand Total | B63: 58.565476 | C63: 19.473809

Sheet Gender
A3: Count of S.No. | B3: Current PhD Status (Completed/In Progress)
A4: Gender | B4: Completed | C4: Grand Total
A5: Female | B5: 109 | C5: 109
A6: Male | B6: 86 | C6: 86
A7: Grand Total | B7: 195 | C7: 195
A11: Gender | B11: Count of S.No.
A12: Female | B12: 135
A13: Male | B13: 105
A14: Grand Total | B14: 240
A19: Count of S.No. | B19: Gender
A20: Cohort | B20: Female | C20: Male | D20: Grand Total
A21: 1 | B21: 0.35 | C21: 0.65 | D21: 1
A22: 2 | B22: 0.4375 | C22: 0.5625 | D22: 1
A23: 3 | B23: 0.57142857 | C23: 0.42857143 | D23: 1
A24: 4 | B24: 0.46153846 | C24: 0.53846154 | D24: 1
A25: 5 | B25: 0.55 | C25: 0.45 | D25: 1
A26: 6 | B26: 0.625 | C26: 0.375 | D26: 1
A27: 7 | B27: 0.75 | C27: 0.25 | D27: 1
A28: 8 | B28: 0.60869565 | C28: 0.39130435 | D28: 1
A29: 9 | B29: 0.59090909 | C29: 0.40909091 | D29: 1
A30: 10 | B30: 0.625 | C30: 0.375 | D30: 1
A31: 11 | B31: 0.55 | C31: 0.45 | D31: 1
A32: Grand Total | B32: 0.5625 | C32: 0.4375 | D32: 1
A38: Cohort | B38: Female | C38: Male | D38: Grand Total
A39: 1 | B39: 7 (40%) | C39: 13 | D39: 20
A40: 2 | B40: 8 | C40: 10 | D40: 18
A41: 3 | B41: 13 | C41: 9 | D41: 22
A42: 4 | B42: 12 | C42: 14 | D42: 26
A43: 5 | B43: 12 | C43: 9 | D43: 21
A44: 6 | B44: 15 | C44: 9 | D44: 24
A45: 7 | B45: 18 | C45: 6 | D45: 24
A46: 8 | B46: 14 | C46: 9 | D46: 23
A47: 9 | B47: 13 | C47: 9 | D47: 22
A48: 10 | B48: 15 | C48: 9 | D48: 24
A49: Grand Total | B49: 127 | C49: 97 | D49: 224
A54: Status | B54: In progress: Above 60 months
A55: Gender | B55: (All)
A57: Count of S.No.
A58: 27

Sheet Sheet8
B4: Status | C4: (Multiple Items)
B6: No. | C6: Gender | H6: =35/40 -> 0.875
B7: Institution of employment at registration | C7: Female | D7: Male | E7: Grand Total
B8: AGINCOURT | D8: 1 | E8: 1
B9: APHRC | C9: 1 | D9: 3 | E9: 4
B10: Ifakara Health Institute | C10: 5 | D10: 2 | E10: 7
B11: Makerere University | C11: 6 | D11: 13 | E11: 19
B12: Moi University | C12: 11 | D12: 2 | E12: 13
B13: Obafemi Awolowo University | C13: 15 | D13: 14 | E13: 29
B14: University of Dar es Salaam | C14: 2 | D14: 2 | E14: 4
B15: University of Ibadan | C15: 18 | D15: 14 | E15: 32
B16: University of Malawi | C16: 9 | D16: 15 | E16: 24
B17: University of Nairobi | C17: 14 | D17: 3 | E17: 17
B18: University of Rwanda | C18: 10 | D18: 10 | E18: 20
B19: University of the Witwatersrand | C19: 18 | D19: 7 | E19: 25
B20: Grand Total | C20: 109 | D20: 86 | E20: 195

Sheet Pivot Table
U2: =60/123 -> 0.48780488
A3: Count of S.No. | B3: Status | K3: Count of S.No. | L3: Status | U3: =63/123 -> 0.51219512
A4: Cohort | B4: In progress: Above 60 months | C4: Completed:Delayed | D4: Completed:On time | E4: Grand Total | K4: Cohort | L4: In progress: Above 60 months | M4: Completed:Delayed | N4: Completed:On time | O4: Grand Total
A5: 1 | C5: 14 | D5: 6 | E5: 20 | K5: 1 | M5: 14 | N5: 6 | O5: 20
A6: 2 | B6: 1 | C6: 9 | D6: 6 | E6: 16 | K6: 2 | L6: 1 | M6: 9 | N6: 6 | O6: 16
A7: 3 | B7: 3 | C7: 8 | D7: 10 | E7: 21 | K7: 3 | L7: 3 | M7: 8 | N7: 10 | O7: 21
A8: 4 | B8: 1 | C8: 19 | D8: 6 | E8: 26 | K8: 4 | L8: 1 | M8: 19 | N8: 6 | O8: 26
A9: 5 | B9: 2 | C9: 15 | D9: 3 | E9: 20 | K9: 5 | L9: 2 | M9: 15 | N9: 3 | O9: 20
A10: 6 | C10: 12 | D10: 12 | E10: 24 | K10: 6 | M10: 12 | N10: 12 | O10: 24
A11: 7 | C11: 13 | D11: 11 | E11: 24 | K11: 7 | M11: 13 | N11: 11 | O11: 24
A12: 8 | B12: 6 | C12: 11 | D12: 6 | E12: 23 | K12: 8 | L12: 6 | M12: 11 | N12: 6 | O12: 23
A13: 9 | B13: 6 | C13: 13 | D13: 3 | E13: 22 | K13: 9 | L13: 6 | M13: 13 | N13: 3 | O13: 22
A14: 10 | B14: 8 | C14: 11 | D14: 5 | E14: 24 | K14: 10 | L14: 8 | M14: 11 | N14: 5 | O14: 24
A15: Grand Total | B15: 27 | C15: 125 | D15: 68 | E15: 220 | K15: Grand Total | L15: 27 | M15: 125 | N15: 68 | O15: 220
A21: Count of S.No. | B21: Status
A22: Cohort | B22: In progress: Above 60 months | C22: Completed:Delayed | D22: Completed:On time | E22: Grand Total
A23: 1 | B23: 0 | C23: 0.7 | D23: 0.3 | E23: 1
A24: 2 | B24: 0.0625 | C24: 0.5625 | D24: 0.375 | E24: 1
A25: 3 | B25: 0.14285714 | C25: 0.38095238 | D25: 0.47619048 | E25: 1
A26: 4 | B26: 0.038461538 | C26: 0.73076923 | D26: 0.23076923 | E26: 1
A27: 5 | B27: 0.1 | C27: 0.75 | D27: 0.15 | E27: 1
A28: 6 | B28: 0 | C28: 0.5 | D28: 0.5 | E28: 1
A29: 7 | B29: 0 | C29: 0.54166667 | D29: 0.45833333 | E29: 1
A30: 8 | B30: 0.26086957 | C30: 0.47826087 | D30: 0.26086957 | E30: 1
A31: 9 | B31: 0.27272727 | C31: 0.59090909 | D31: 0.13636364 | E31: 1
A32: 10 | B32: 0.33333333 | C32: 0.45833333 | D32: 0.20833333 | E32: 1
A33: Grand Total | B33: 0.12272727 | C33: 0.56818182 | D33: 0.30909091 | E33: 1
A37: Count of S.No. | B37: Status
A38: Gender | B38: In progress: Above 60 months | C38: Completed:Delayed | D38: Completed:On time | E38: Grand Total
A39: Female | B39: 17 | C39: 69 | D39: 38 | E39: 124
A40: Male | B40: 10 | C40: 56 | D40: 30 | E40: 96
A41: Grand Total | B41: 27 | C41: 125 | D41: 68 | E41: 220
A44: Current PhD Status (Completed/In Progress) | B44: Completed
A46: Count of S.No. | B46: Gender
A47: Date of completion (Defended/Graduated) | B47: Female | C47: Male | D47: Grand Total
A48: 2013 | B48: 1 | C48: 2 | D48: 3
A49: 2014 | B49: 2 | C49: 3 | D49: 5
A50: 2015 | B50: 2 | C50: 6 | D50: 8
A51: 2016 | B51: 7 | C51: 9 | D51: 16
A52: 2017 | B52: 8 | C52: 7 | D52: 15
...

Sheet Institution of registration
A2: Count of S.No. | B2: Status
A3: Institution of registration | B3: In progress: Above 60 months | C3: Completed:Delayed | D3: Completed:On time | E3: Grand Total
A4: Makerere University | B4: 1 | C4: 12 | D4: 5 | E4: 18
A5: Moi University | B5: 4 | C5: 5 | D5: 2 | E5: 11
A6: Obafemi Awolowo University | C6: 3 | D6: 17 | E6: 20
A7: University of Dar es Salaam | C7: 4 | D7: 2 | E7: 6
A8: University of Ibadan | B8: 4 | C8: 16 | D8: 12 | E8: 32
A9: University of Nairobi | B9: 5 | C9: 14 | D9: 8 | E9: 27
A10: University of Rwanda | B10: 2 | C10: 6 | E10: 8
A11: University of the Witwatersrand | B11: 9 | C11: 56 | D11: 15 | E11: 80
A12: University of Malawi | B12: 2 | C12: 9 | D12: 7 | E12: 18
A13: Grand Total | B13: 27 | C13: 125 | D13: 68 | E13: 220
A19: Count of S.No. | B19: Status
A20: Institution of registration | B20: In progress: Above 60 months | C20: Completed:Delayed | D20: Completed:On time | E20: Grand Total
A21: Makerere University | B21: 0.055555556 | C21: 0.66666667 | D21: 0.27777778 | E21: 1
A22: Moi University | B22: 0.36363636 | C22: 0.45454545 | D22: 0.18181818 | E22: 1
A23: Obafemi Awolowo University | B23: 0 | C23: 0.15 | D23: 0.85 | E23: 1
A24: University of Dar es Salaam | B24: 0 | C24: 0.66666667 | D24: 0.33333333 | E24: 1
A25: University of Ibadan | B25: 0.125 | C25: 0.5 | D25: 0.375 | E25: 1
A26: University of Nairobi | B26: 0.18518519 | C26: 0.51851852 | D26: 0.2962963 | E26: 1
A27: University of Rwanda | B27: 0.25 | C27: 0.75 | D27: 0 | E27: 1
A28: University of the Witwatersrand | B28: 0.1125 | C28: 0.7 | D28: 0.1875 | E28: 1
A29: University of Malawi | B29: 0.11111111 | C29: 0.5 | D29: 0.38888889 | E29: 1
A30: Grand Total | B30: 0.12272727 | C30: 0.56818182 | D30: 0.30909091 | E30: 1

Sheet Time in the program
B1: Gender | C1: (All)
B2: Status | C2: (All)
C4: Cohort
B5: Unique ID | C5: 1 | D5: 2 | E5: 3 | F5: 4 | G5: 5 | H5: 6 | I5: 7 | J5: 8 | K5: 9 | L5: 10
B6: C1/001
B7: C1/002
B8: C1/003
B9: C1/004
B10: C1/005
B11: C1/006
B12: C1/007
B13: C1/008
B14: C1/009
B15: C1/010
B16: C1/011
B17: C1/012
... B225: C9/023

Sheet Sheet5
B1: Home institution | C1: In progress >60months | D1: In progress <60 months | E1: Completed
B2: AGINCOURT | E2: 1 | F2: =SUM(C2:E2) -> 1
B3: APHRC | E3: 4 | F3: =SUM(C3:E3) -> 4
B4: Ifakara Health Institute | D4: 1 | E4: 6 | F4: =SUM(C4:E4) -> 7
B5: Makerere University | C5: 3 | E5: 18 | F5: =SUM(C5:E5) -> 21
B6: Moi University | C6: 7 | E6: 12 | F6: =SUM(C6:E6) -> 19
B7: Obafemi Awolowo University | D7: 4 | E7: 27 | F7: =SUM(C7:E7) -> 31
B8: University of Dar es Salaam | E8: 4 | F8: =SUM(C8:E8) -> 4
B9: University of Ibadan | C9: 4 | D9: 3 | E9: 29 | F9: =SUM(C9:E9) -> 36
B10: University of Malawi | C10: 4 | D10: 3 | E10: 20 | F10: =SUM(C10:E10) -> 27
B11: University of Nairobi | C11: 4 | D11: 1 | E11: 15 | F11: =SUM(C11:E11) -> 20
B12: University of Rwanda | C12: 7 | D12: 4 | E12: 13 | F12: =SUM(C12:E12) -> 24
B13: University of the Witwatersrand | C13: 8 | D13: 3 | E13: 19 | F13: =SUM(C13:E13) -> 30
B14: Grand Total | C14: 37 | D14: 19 | E14: 168 | F14: =SUM(C14:E14) -> 224
