Workbook

Sheet Dashboard
S2: Overall retention rate | T2: ='Pivot Analysis'!F41 -> 0.90566038
S3: Retention rate | T3: ='Pivot Analysis'!F41 -> 0.90566038
S4: Cohort 1 | T4: ='Pivot Analysis'!F30 -> 0.86956522
S5: Cohort 2 | T5: ='Pivot Analysis'!F31 -> 0.8
S6: Cohort 3 | T6: ='Pivot Analysis'!F32 -> 0.91304348
S7: Cohort 4 | T7: ='Pivot Analysis'!F33 -> 0.96296296
S8: Cohort 5 | T8: ='Pivot Analysis'!F34 -> 0.8
S9: Cohort 6 | T9: ='Pivot Analysis'!F35 -> 0.96
S10: Cohort 7 | T10: ='Pivot Analysis'!F36 -> 0.88888889
S11: Cohort 8 | T11: ='Pivot Analysis'!F37 -> 0.88461538
S12: Cohort 9 | T12: ='Pivot Analysis'!F38 -> 0.91666667
S13: Cohort 10 | T13: ='Pivot Analysis'!F39 -> 0.96
B41: Distribution active fellows by Cohort
B42: Count of Unique ID | C42: Current PhD Status ( Completed/Defended/In Progress)
B43: Cohort | C43: Completed | D43: In progress | E43: Terminated | F43: Grand Total | G43: Retention rate | S43: =2 -> 2
B44: 1 | C44: 20 | E44: 3 | F44: 23
B45: 2 | C45: 15 | D45: 1 | E45: 4 | F45: 20
B46: 3 | C46: 18 | D46: 3 | E46: 2 | F46: 23
B47: 4 | C47: 25 | D47: 1 | E47: 1 | F47: 27
B48: 5 | C48: 18 | D48: 2 | E48: 5 | F48: 25
B49: 6 | C49: 24 | E49: 1 | F49: 25
B50: 7 | C50: 24 | E50: 3 | F50: 27 | H50: -
B51: 8 | C51: 17 | D51: 6 | E51: 3 | F51: 26
B52: 9 | C52: 16 | D52: 6 | E52: 2 | F52: 24
B53: 10 | C53: 17 | D53: 7 | E53: 1 | F53: 25
B54: 11 | D54: 20 | F54: 20
B55: Grand Total | C55: 194 | D55: 46 | E55: 25 | F55: 265

Sheet Pivot Analysis
A1: Active fellows by institution of registration | H1: Active fellows by institution of employment | S1: Cohort | T1: Male | U1: Female | V1: Total
A2: Gender | B2: (All) | H2: Gender | I2: (All) | N2: Current PhD Status ( Completed/Defended/In Progress) | O2: (All) | P2: Current PhD Status ( Completed/Defended/In Progress) | Q2: Completed | S2: University of Ibadan
N3: Distribution active fellows by Cohort | P3: Distribution active fellows by Cohort
A4: Count of Unique ID | B4: Current PhD Status ( Completed/Defended/In Progress) | H4: Count of Unique ID | I4: Current PhD Status ( Completed/Defended/In Progress) | N4: Gender | O4: Count of Unique ID | P4: Gender | Q4: Count of Unique ID
A5: Institution of registration | B5: Completed | C5: In progress | D5: Terminated | E5: Grand Total | H5: Institution of employment at registration | I5: Completed | J5: In progress | K5: Terminated | L5: Grand Total | N5: Female | O5: 147 | P5: Female | Q5: 108
A6: Makerere University | B6: 17 | C6: 3 | D6: 3 | E6: 23 | H6: AGINCOURT | I6: 1 | J6: 1 | L6: 2 | N6: Male | O6: 118 | P6: Male | Q6: 86
A7: Moi University | B7: 7 | C7: 5 | E7: 12 | H7: APHRC | I7: 4 | K7: 1 | L7: 5 | N7: Grand Total | O7: 265 | P7: Grand Total | Q7: 194
A8: Obafemi Awolowo University | B8: 19 | C8: 1 | E8: 20 | H8: Ifakara Health Institute | I8: 7 | J8: 1 | K8: 1 | L8: 9
A9: University of Dar es Salaam | B9: 6 | D9: 2 | E9: 8 | H9: Makerere University | I9: 19 | J9: 4 | K9: 4 | L9: 27
A10: University of Ibadan | B10: 28 | C10: 7 | E10: 35 | H10: Moi University | I10: 13 | J10: 7 | K10: 1 | L10: 21
A11: University of Nairobi | B11: 22 | C11: 8 | D11: 5 | E11: 35 | H11: Obafemi Awolowo University | I11: 29 | J11: 4 | L11: 33
A12: University of Rwanda | B12: 6 | C12: 2 | E12: 8 | H12: University of Dar es Salaam | I12: 4 | K12: 2 | L12: 6
A13: University of the Malawi | B13: 16 | C13: 2 | D13: 3 | E13: 21 | H13: University of Ibadan | I13: 32 | J13: 7 | L13: 39
A14: University of the Witwatersrand | B14: 73 | C14: 9 | D14: 8 | E14: 90 | H14: University of Malawi | I14: 24 | J14: 6 | K14: 3 | L14: 33
A15: (blank) | C15: 9 | D15: 4 | E15: 13 | H15: University of Nairobi | I15: 17 | J15: 6 | K15: 7 | L15: 30
A16: Grand Total | B16: 194 | C16: 46 | D16: 25 | E16: 265 | H16: University of Rwanda | I16: 20 | J16: 6 | K16: 1 | L16: 27
H17: University of the Witwatersrand | I17: 24 | J17: 2 | K17: 5 | L17: 31
H18: Somali National University | J18: 2 | L18: 2
H19: Grand Total | I19: 194 | J19: 46 | K19: 25 | L19: 265
A27: Distribution active fellows by Cohort | H27: Current PhD Status ( Completed/Defended/In Progress) | I27: (All)
A28: Count of Unique ID | B28: Current PhD Status ( Completed/Defended/In Progress)
A29: Cohort | B29: Completed | C29: In progress | D29: Terminated | E29: Grand Total | F29: Retention Rate | H29: Count of Unique ID | I29: Gender
A30: 1 | B30: 20 | D30: 3 | E30: 23 | F30: =SUM(B30:C30)/E30 -> 0.86956522 | H30: Nationality | I30: Female | J30: Male | K30: Grand Total | N30: Cohort 1-10 Demographics.xlsx]Fellows!A1:CJ266
A31: 2 | B31: 15 | C31: 1 | D31: 4 | E31: 20 | F31: =SUM(B31:C31)/E31 -> 0.8 | H31: Kenya | I31: 40 | J31: 15 | K31: 55
A32: 3 | B32: 18 | C32: 3 | D32: 2 | E32: 23 | F32: =SUM(B32:C32)/E32 -> 0.91304348 | H32: Malawi | I32: 12 | J32: 22 | K32: 34
A33: 4 | B33: 25 | C33: 1 | D33: 1 | E33: 27 | F33: =SUM(B33:C33)/E33 -> 0.96296296 | H33: Nigeria | I33: 42 | J33: 32 | K33: 74
A34: 5 | B34: 18 | C34: 2 | D34: 5 | E34: 25 | F34: =SUM(B34:C34)/E34 -> 0.8 | H34: Rwanda | I34: 11 | J34: 16 | K34: 27
A35: 6 | B35: 24 | D35: 1 | E35: 25 | F35: =SUM(B35:C35)/E35 -> 0.96 | H35: Senegal | J35: 1 | K35: 1
A36: 7 | B36: 24 | D36: 3 | E36: 27 | F36: =SUM(B36:C36)/E36 -> 0.88888889 | H36: Somalia | I36: 1 | J36: 1 | K36: 2
A37: 8 | B37: 17 | C37: 6 | D37: 3 | E37: 26 | F37: =SUM(B37:C37)/E37 -> 0.88461538 | H37: South Africa | I37: 19 | J37: 8 | K37: 27
A38: 9 | B38: 16 | C38: 6 | D38: 2 | E38: 24 | F38: =SUM(B38:C38)/E38 -> 0.91666667 | H38: Tanzania | I38: 9 | J38: 6 | K38: 15
A39: 10 | B39: 17 | C39: 7 | D39: 1 | E39: 25 | F39: =SUM(B39:C39)/E39 -> 0.96 | H39: Uganda | I39: 11 | J39: 16 | K39: 27
A40: 11 | C40: 20 | E40: 20 | F40: =SUM(B40:C40)/E40 -> 1 | H40: Zimbabwe | I40: 2 | J40: 1 | K40: 3
A41: Grand Total | B41: 194 | C41: 46 | D41: 25 | E41: 265 | F41: =SUM(B41:C41)/E41 -> 0.90566038 | H41: Grand Total | I41: 147 | J41: 118 | K41: 265
P57: =109/245 -> 0.44489796
P58: =136/245 -> 0.55510204
A62: Current PhD Status ( Completed/Defended/In Progress) | B62: In progress
A64: Count of Unique ID | B64: Gender
A65: Cohort | B65: Female | C65: Male | D65: Grand Total | H65: Cohort
A66: 2 | C66: 1 | D66: 1 | H66: Count of Unique ID | I66: Current PhD Status ( Completed/Defended/In Progress)
...

Sheet Sheet2
A3: Count of S.No. | B3: Column Labels
A4: Row Labels | B4: Completed | C4: In progress | D4: Terminated | E4: Grand Total
A5: 1 | B5: 20 | D5: 3 | E5: 23
A6: 2 | B6: 15 | C6: 1 | D6: 4 | E6: 20
A7: 3 | B7: 18 | C7: 3 | D7: 2 | E7: 23
A8: 4 | B8: 25 | C8: 1 | D8: 1 | E8: 27
A9: 5 | B9: 18 | C9: 2 | D9: 5 | E9: 25
A10: 6 | B10: 24 | D10: 1 | E10: 25
A11: 7 | B11: 24 | D11: 3 | E11: 27
A12: 8 | B12: 17 | C12: 6 | D12: 3 | E12: 26
A13: 9 | B13: 16 | C13: 6 | D13: 2 | E13: 24
A14: 10 | B14: 17 | C14: 7 | D14: 1 | E14: 25
A15: Grand Total | B15: 194 | C15: 26 | D15: 25 | E15: 245
A20: Count of S.No. | B20: Column Labels
A21: Row Labels | B21: Completed | C21: In progress | D21: Terminated | E21: Grand Total
A22: Female | B22: 108 | C22: 16 | D22: 12 | E22: 136
A23: Male | B23: 86 | C23: 10 | D23: 13 | E23: 109
A24: Grand Total | B24: 194 | C24: 26 | D24: 25 | E24: 245
C33: =65+78+32+49+12+9 -> 245
B34: Row Labels | C34: Female | D34: Male | E34: Grand Total
B35: Completed | C35: 80 | D35: 65 | E35: 145
B36: In progress | C36: 47 | D36: 32 | E36: 79
B37: Terminated | C37: 9 | D37: 12 | E37: 21
B38: Grand Total | C38: 136 | D38: 109 | E38: 245

Sheet Fellows
A1: S.No. | B1: Unique ID | C1: First Name | D1: Middle Name | E1: Surname | F1: Gender | G1: Cohort | H1: Nationality | I1: Institution of employment at registration | J1: Discipline | K1: Department | L1: Institution of registration | M1: Registered at Home | N1: PhD Student Number at Host Institution | O1: Marital Status at enrolment | P1: Current Marital Status | Q1: Marital Status at Completion | R1: Email | S1: Alternative e-mail | T1: Phone | U1: Masters Degree | V1: DOB | W1: Proposed Research Title | X1: Type of study | Y1: Laboratory work? | Z1: Type of data | AA1: Ranking | AB1: Date of PhD registration | AC1: Year of admission into CARTA | AD1: Terminated | AE1: 1st Supervisors | AF1: 2nd Supervisor | AG1: 3rd Supervisor | AH1: Number of supervisors | AI1: Institution for 1st Supervisor | AJ1: Institution for 2nd Supervisor | AK1: Institution for 3rd Supervisor | AL1: 1st Supervisors workshop Attendance | AM1: 2nd Supervisors workshop Attendance | AN1: 3rd Supervisors workshop Attendance | AO1: Type of employment | AP1: Position at Enrollment | AQ1: Current Position | AR1: Promotion event | AS1: Other responsibilities | AT1: Current Institution (Year of change in ()) | AU1: ORCID | AV1: Suspensions | AW1: Month/ Year JAS1 | AX1: Month/ Year JAS2 | AY1: Attended JAS 2 on time | AZ1: Date of protocol submission to PG | BA1: Date of protocol submission to IRB | BB1: Date of Ethics approval | BC1: Approcved research topic | BD1: Month/ Year JAS3 | BE1: Attended JAS 3 on time | BF1: Month/ Year JAS4 | BG1: Attended JAS 4 on time | BH1: Date of submission of dissertation for examination | BI1: Date of defense | BJ1: Date of submission of corrections | BK1: Date of completion(Defended/Graduated) | BL1: Current PhD Status ( Completed/Defended/In Progress) | BM1: Time to completion since enrolling CARTA (Months) | BN1: Time to completion since PhD registration (Months) | BO1: Thesis title | BP1: No of Publications at Enrollment | BQ1: No of Publications During PhD | BR1: No of Publications after PhD | BS1: 1st Author PhD Publications | BT1: Last Author PhD Publications | BU1: 1st Author Graduate Publications | BV1: Last Author Graduate Publications | BW1: Baby Minder (Event, Year) | BX1: Taken on leave of absence (Yes/No) | BY1: Reason for taking leave of absence | BZ1: Leave start Date | CA1: Leave end Date | CB1: Time taken on leave (months) | CC1: Teacher Replacement | CD1: Teacher replacement start Date | CE1: Teacher replacement end Date | CF1: No. of Children at Entry in CARTA | CG1: No. of children at graduation | CH1: No of Publications for Graduation | CI1: Fellow Funder
A2: 1 | B2: C1/001 | C2: Babatunde | D2: Olubayo | E2: Adedokun | F2: Male | G2: 1 | H2: Nigeria | I2: University of Ibadan | J2: Epidemiology & Medical Biostatistics | K2: Epidemiology and Medical Statistics | L2: University of Ibadan | M2: Yes | O2: Married | P2: Married | Q2: Married | R2: badedokun@cartafrica.org | S2: tukankar@yahoo.co.uk | U2: M.Sc Epidemiology & Medical Statistics | V2: 28116 | W2: Joint modelling of CD4 counts and time to loss to follow up among HIV patients attending antiretroviral clinics in Nigeria | X2: Clinical research | Y2: yes | Z2: Primary | AA2: 16.5 | AB2: 40603 | AC2: 40603 | AE2: Prof Afolabi Bamgboye | AF2: Prof. Olusola Ayeni | AH2: =COUNTA(AE2:AG2) -> 2 | AI2: Home | AJ2: Host | AL2: Yes | AM2: No | AO2: Academic | AQ2: Lecturer | AR2: Yes | AT2: UNIVERSITY OF CHICAGO, UNITED STATES | AU2: 0000-0002-6893-6468 | AW2: 40634 | AX2: 40878 | AY2: Yes | BD2: 41456 | BE2: Yes | BF2: 41699 | BG2: Yes | BK2: 42766 | BL2: Completed | BM2: =DATEDIF(AW2,BK2, "M")+1 -> 70 | BN2: =DATEDIF(AX2,BK2, "M")+1 -> 62 | BP2: 20 | BQ2: 29 | BR2: 26 | BS2: 2 | BT2: 3 | BU2: 0 | BV2: 0 | BW2: No | BX2: No | CC2: No | CF2: 0 | CG2: 1 | CI2: NF
A3: 2 | B3: C1/002 | C3: Celine | E3: Niwemahoro | F3: Female | G3: 1 | H3: Rwanda | I3: University of Rwanda | J3: Demography & Population Studies | K3: Applied Statistics | L3: University of Dar es Salaam | M3: No | O3: Married | P3: Married | R3: cniwemahoro@cartafrica.org | S3: ncmahoro2000@yahoo.fr | T3: +250788350522/254723489604 | U3: Masters in Demography and Population Studies (online) | V3: 29416 | W3: Premarital Fertility and Use Of Health Care: Effect On HIV And Prevention Mother-To-Child Transmission (PMTCT) In Rwanda | X3: Field | Y3: No | Z3: Primary | AA3: 26 | AB3: 40616 | AC3: 40603 | AE3: Dr. Julius Kivelia | AH3: =COUNTA(AE3:AG3) -> 1 | AI3: Host | AL3: Yes | AO3: Academic | AP3: Assistant Lecturer | AQ3: Researcher | AR3: Yes | AT3: SCUB - CONSULTANCY FIRM NAIROBI | AU3: 0000-0003-2008-3061 | AW3: 40637 | AX3: 40878 | AY3: Yes | AZ3: 41186 | BB3: 41473 | BC3: Premarital pregnancies and experiences in antenatal care health seeking behavior in Huye District, Rwanda | BD3: 41458 | BE3: Yes | BF3: 41700 | BG3: Yes | BH3: 42986 | BI3: 43006 | BJ3: 43023 | BK3: 43023 | BL3: Completed | BM3: =DATEDIF(AW3,BK3, "M")+1 -> 79 | BN3: =DATEDIF(AX3,BK3, "M")+1 -> 71 | BO3: Premarital pregnancies and experiences in antenatal care health seeking behavior in Huye District, Rwanda | BP3: 0 | BQ3: 0 | BR3: 0 | BS3: 0 | BT3: 0 | BU3: 0 | BV3: 0 | BW3: No | BX3: No | CC3: No | CF3: 2 | CG3: 2 | CH3: 0 | CI3: NF
A4: 3 | B4: C1/003 | C4: Caroline | D4: Sultan | E4: Sambai | F4: Female | G4: 1 | H4: Kenya | I4: Moi University | J4: Literature | K4: LITERATURE THEATRE AND FILM STUDIES | L4: Moi University | M4: Yes | N4: SASS/DPHIL/LIT/07/11 | P4: Married | R4: csambai@cartafrica.org | S4: carolsambai11@gmail.com | T4: +254722433561 | U4: MA in Africa Literature | V4: 29767 | W4: Television Drama as in Kenya and the Framing of Issues of HIV/AIDS and sexuality | X4: Field | Y4: No | Z4: Primary | AA4: 2.5 | AB4: 40827 | AC4: 40603 | AE4: Prof Christopher Joseph Odhiambo | AF4: Prof. Peter Tirop Simatei | AG4: Caroline Kabiru | AH4: =COUNTA(AE4:AG4) -> 3 | AI4: Home | AJ4: Host | AK4: Other | AL4: Yes | AM4: No | AN4: Yes | AO4: Academic | AP4: Lecturer | AQ4: Lecturer | AR4: Yes | AT4: MOI UNIVERSITY | AU4: 0000-0002-5122-3621 | AW4: 40634 | AX4: 40878 | AY4: Yes | BD4: 41456 | BE4: Yes | BF4: 41701 | BG4: Yes | BK4: 41729 | BL4: Completed | BM4: =DATEDIF(AW4,BK4, "M")+1 -> 36 | BN4: =DATEDIF(AX4,BK4, "M")+1 -> 28 | BP4: 0 | BQ4: 1 | BR4: 1 | BS4: 2 | BT4: 0 | BU4: 0 | BV4: 0 | BW4: JAS 2, 2011 | BX4: No | CC4: No | CF4: NF | CG4: NF | CI4: NF
A5: 4 | B5: C1/004 | C5: Dieudonne | E5: Uwizeye | F5: Male | G5: 1 | H5: Rwanda | I5: University of Rwanda | J5: Demography & Population Studies | K5: Sustainable Development | L5: University of Dar es Salaam | M5: No | O5: Married | P5: Married | Q5: Married | R5: duwizeye@cartafrica.org | S5: dr.uwizeye@gmail.com | T5: (+250) 0788 457 397 | U5: MA English and MA in Development Studies | V5: 29587 | W5: Review Of Environmental And Population Health Challenges In The Rwandan Towns And Innovative Mitigation Strategies For Improved And Sustainble life | X5: Field | Y5: No | Z5: Primary | AA5: 24 | AB5: 40695 | AC5: 40603 | AE5: Dr. Sokoni Cosmas Hassan | AH5: =COUNTA(AE5:AG5) -> 1 | AI5: Host | AJ5: Other | AL5: Yes | AM5: Yes | AO5: Academic | AP5: Assistant Lecturer | AQ5: Associate Professor | AR5: Yes | AS5: Head of Department Deputy Team Leader of a Research Subprogram in Peace, Conflict and Security Studies at the Center for Conflict Management, University of Rwanda. | AT5: UNIVERSITY OF RWANDA | AU5: 0000-0002-9733-8969 | AW5: 40634 | AX5: 40878 | AY5: Yes | BD5: 41456 | BE5: Yes | BF5: 41702 | BG5: Yes | BK5: 42338 | BL5: Completed | BM5: =DATEDIF(AW5,BK5, "M")+1 -> 56 | BN5: =DATEDIF(AX5,BK5, "M")+1 -> 48 | BP5: 0 | BQ5: 2 | BR5: 7 | BS5: 2 | BT5: 0 | BU5: 0 | BV5: 0 | BW5: No | BX5: No | CC5: Yes | CF5: 1 | CG5: 3 | CI5: NF
A6: 5 | B6: C1/005 | C6: Wells | E6: Utembe | F6: Male | G6: 1 | H6: Malawi | I6: University of Malawi | J6: Environmental Sciences | K6: Physics and Biochemical Sciences | L6: University of the Witwatersrand | M6: No | O6: Married | P6: Married | Q6: Married | R6: wutembe@cartafrica.org | S6: wutembe@poly.ac.mw | U6: Msc Environemntal (online) | V6: 26178 | W6: Assessment of occurrence, profile, distribution and exposure to polycyclic aromatic hydrocarbons (PAHs) in Malawi | X6: Clinical research | Y6: yes | Z6: Primary | AA6: 21 | AB6: 40646 | AC6: 40603 | AE6: Prof Mary Gulumian | AF6: Dr. Louisa Alfazema | AH6: =COUNTA(AE6:AG6) -> 2 | AI6: Host | AJ6: Home | AL6: Yes | AM6: No | AO6: Academic | AP6: Lecturer | AQ6: Senior Medical Epidemiologist | AR6: Yes | AT6: NATIONAL INSTITUTE FOR OCCUPATIONAL HEALTH, SOUTH AFRICA (2012) | AU6: 0000-0001-6547-7692 | AW6: 40634 | AX6: 40878 | AY6: Yes | BD6: 41456 | BE6: Yes | BF6: 42064 | BG6: No | BK6: 42551 | BL6: Completed | BM6: =DATEDIF(AW6,BK6, "M")+1 -> 63 | BN6: =DATEDIF(AX6,BK6, "M")+1 -> 55 | BP6: 0 | BQ6: 5 | BR6: 15 | BS6: 4 | BT6: 0 | BU6: 0 | BV6: 0 | BW6: No | BX6: No | CC6: No | CF6: NF | CG6: NF | CI6: NF
A7: 6 | B7: C1/006 | C7: Victoria | D7: Mathew | E7: Mwakalinga Chuma | F7: Female | G7: 1 | H7: Tanzania | I7: Ifakara Health Institute | J7: Biomedical and environmental sciences | L7: University of the Witwatersrand | M7: No | O7: Married | P7: married | Q7: Married | R7: vmwakalinga@cartafrica.org | S7: vmwakalinga@ihi.or.tz | T7: +255 738 357315; +255 767 366 539 | U7: Msc Urban Planing and Management | V7: 28383 | W7: Integrated geographical tools can enable targeted urban planning interventions to control malaria and lymphatic filariasis | X7: Field | Y7: No | Z7: Primary | AA7: 16 | AB7: 40609 | AC7: 40603 | AE7: Dr. Maureen Coetzee | AF7: Dr. Gerry Killeen | AG7: Dr. Stefan Dongus | AH7: =COUNTA(AE7:AG7) -> 3 | AI7: Host | AJ7: Home | AK7: Home | AL7: Yes | AM7: Yes | AN7: No | AO7: Researcher | AP7: Assistant lecturer | AQ7: Senior Lecturer | AR7: Yes | AT7: ARTHI UNIVERSITY | AW7: 40634 | AX7: 40878 | AY7: Yes | BD7: 41456 | BE7: Yes | BF7: 41699 | BG7: Yes | BK7: 43073 | BL7: Completed | BM7: =DATEDIF(AW7,BK7, "M")+1 -> 81 | BN7: =DATEDIF(AX7,BK7, "M")+1 -> 73 | BP7: NF | BQ7: 4 | BR7: 1 | BS7: 0 | BT7: 0 | BU7: 0 | BV7: 1 | BW7: JAS 1, 2011 | BX7: No | CC7: No | CF7: 3 | CG7: 3 | CI7: NF
A8: 7 | B8: C1/007 | C8: Esnat | D8: Dorothy | E8: Chirwa | F8: Female | G8: 1 | H8: Malawi | I8: University of Malawi | J8: Mathematical Sciences | K8: DPHRU Wits | L8: University of the Witwatersrand | M8: No | O8: Married | P8: Married | Q8: Married | R8: echirwa@cartafrica.org | S8: echirwa@chanco.unima.mw edkwalira@yahoo.com, | U8: Masters in Biometry (online) | V8: 26090 | W8: Modelling longitudinal child growth within the Birth to Twenty (Soweto) and Lungwena (Mangochi, Malawi) cohorts | X8: Field | Y8: No | Z8: Primary | AA8: 7.5 | AB8: 40577 | AC8: 40603 | AE8: Prof Shane Norris | AF8: Dr. Paula Griffiths | AG8: Assoc Prof. Ken Maleta | AH8: =COUNTA(AE8:AG8) -> 3 | AI8: Host | AJ8: Other | AK8: Home | AL8: Yes | AM8: No | AN8: No | AO8: Academic | AP8: Lecturer | AQ8: Senior Biostatistician | AR8: Yes | AT8: SOUTH AFRICA MEDICAL RESEARCH COUNCIL | AU8: 0000-0003-0471-4978 | AW8: 40634 | AX8: 40878 | AY8: Yes | BD8: 41456 | BE8: Yes | BF8: 41700 | BG8: Yes | BK8: 42674 | BL8: Completed | BM8: =DATEDIF(AW8,BK8, "M")+1 -> 67 | BN8: =DATEDIF(AX8,BK8, "M")+1 -> 59 | BP8: 1 | BQ8: 7 | BR8: 47 | BS8: 3 | BT8: 0 | BU8: 0 | BV8: 0 | BW8: No | BX8: No | CC8: No | CF8: 2 | CG8: 2 | CI8: NF
A9: 8 | B9: C1/008 | C9: Taofeek | D9: Oluwole | E9: Awotidebe | F9: Male | G9: 1 | H9: Nigeria | I9: Obafemi Awolowo University | J9: Exercise Physiology | K9: Human Kinetics and Health Education | L9: University of Ibadan | M9: No | N9: 125847 | O9: Married | P9: Married | R9: tawotidebe@cartafrica.org | S9: tidebet@yahoo.com | T9: +2348037196021 | U9: M.SC Physiotherapy | V9: 26085 | W9: Cardiovascular Risk Profile And Physical Activity Level of Residents of a Semi – Urban Community In Nigeria | X9: Field | Y9: No | Z9: Primary | AA9: 14 | AB9: 40739 | AC9: 40603 | AE9: Professor Babalola Joseph Folorunso | AF9: Professor Lateef Babatunde Salako | AH9: =COUNTA(AE9:AG9) -> 2 | AI9: Other | AL9: Yes | AO9: Academic | AP9: Lecturer II | AQ9: Senior Lecturer | AR9: Yes | AS9: Vice Dean of the Faculty of Basic Medical Sciences, College of Health Sciences | AT9: OBAFEMI AWOLOWO UNIVERSITY | AU9: 0000-0002-8583-9467 | AW9: 40634 | AX9: 40878 | AY9: Yes | BD9: 41456 | BE9: Yes | BF9: 41701 | BG9: Yes | BK9: 42325 | BL9: Completed | BM9: =DATEDIF(AW9,BK9, "M")+1 -> 56 | BN9: =DATEDIF(AX9,BK9, "M")+1 -> 48 | BP9: 5 | BQ9: 12 | BR9: 10 | BS9: 6 | BT9: 4 | BU9: 2 | BV9: 0 | BW9: No | BX9: No | CC9: No | CF9: NF | CG9: NF | CI9: NF
A10: 9 | B10: C1/009 | C10: Fresier | E10: Maseko | F10: Male | G10: 1 | H10: Malawi | I10: University of Malawi | J10: Community Health | K10: Department of Community Health | L10: University of the Malawi | M10: Yes | P10: NF | R10: fmaseko@cartafrica.org | S10: fcmaseko@yahoo.com fmaseko@medcol.mw | U10: Master of Public Health(online) | V10: 26541 | W10: Maximizing utilization of cervical cancer prevention services in South East Health Zone of Malawi. What would it take? | X10: Field | Y10: No | Z10: Primary | AA10: 11 | AB10: 40544 | AC10: 40603 | AE10: Dr. Maureen Leah Chirwa | AF10: Dr. Adamson Muula | AH10: =COUNTA(AE10:AG10) -> 2 | AI10: Home | AJ10: Host | AL10: Yes | AM10: Yes | AO10: Academic | AQ10: Lecturer | AT10: UNIVERSITY OF MALAWI | AU10: 0000-0002-0996-4207 | AW10: 40634 | AX10: 40878 | AY10: Yes | BD10: 41456 | BE10: Yes | BF10: 41702 | BG10: Yes | BK10: 42613 | BL10: Completed | BM10: =DATEDIF(AW10,BK10, "M")+1 -> 65 | BN10: =DATEDIF(AX10,BK10, "M")+1 -> 57 | BP10: 7 | BQ10: 6 | BR10: 1 | BS10: 3 | BT10: 1 | BU10: 0 | BV10: 0 | BW10: No | BX10: No | CC10: No | CF10: NF | CG10: NF | CI10: NF
A11: 10 | B11: C1/010 | C11: François | E11: Niragire | F11: Male | G11: 1 | H11: Rwanda | I11: University of Rwanda | J11: Statistics | K11: Applied Statistics | L11: University of Rwanda | M11: Yes | N11: 213004253 | O11: Married | P11: Married | Q11: Married | R11: fniragire@cartafrica.org | S11: fniragire@ur.ac.rw; fniragiree@gmail.com; fniragire@gmail.com | T11: +250 78 8273787/+250787427688 | U11: MSc. In Social Statistics | V11: 26915 | W11: Spatial modeling of the relationship between HIV prevalence and socioeconomic determinants of child mortality in Rwanda. | X11: Field | Y11: No | Z11: Secondary | AA11: 13 | AB11: 40823 | AC11: 40603 | AE11: Dr. Thomas N. O. Achia | AF11: Dr. Lyambabaje Alexandre | AG11: Joseph Ntaganira | AH11: =COUNTA(AE11:AG11) -> 3 | AI11: Other | AJ11: Home | AK11: Home | AL11: Yes | AM11: Yes | AN11: No | AO11: Academic | AP11: Assistant Lecturer | AQ11: Professor | AR11: Yes | AS11: Director of Teaching and Learning, Director of Research and Innovation at he College of Business and Economics (2022) | AT11: UNIVERSITY OF RWANDA | AU11: 0000-0003-0473-387 | AW11: 40634 | AX11: 40878 | AY11: Yes | AZ11: 40672 | BB11: 41298 | BD11: 41484 | BE11: Yes | BF11: 41703 | BG11: Yes | BH11: 42507 | BI11: 42947 | BJ11: 42967 | BK11: 42947 | BL11: Completed | BM11: =DATEDIF(AW11,BK11, "M")+1 -> 76 | BN11: =DATEDIF(AX11,BK11, "M")+1 -> 68 | BO11: Spatial modelling of the relationship between HIV prevalence and determinants of child mortality in Rwanda | BP11: 0 | BQ11: 4 | BR11: 9 | BS11: 1 | BT11: 4 | BU11: 0 | BV11: 0 | BW11: No | BX11: No | CC11: No | CF11: 3 | CG11: 4 | CI11: NF
A12: 11 | B12: C1/011 | C12: Joshua | D12: Odunayo | E12: Akinyemi | F12: Male | G12: 1 | H12: Nigeria | I12: University of Ibadan | J12: Epidemiology & Medical Statistics | K12: Epidemiology and Medical Statistics | L12: University of Ibadan | M12: Yes | O12: Single | P12: Married | Q12: Married | R12: jakinyemi@cartafrica.org | S12: odunjoshua@yahoo.com joakinyemi@com.ui.edu.ng | T12: +234-8077677427 | U12: MSc (Medical Statistics) | V12: 28098 | W12: Levels, Trends and Differentials of Infant and Child Mortality in Nigeria: 1990 - 2008 | X12: Field | Y12: No | Z12: Secondary | AA12: 21 | AB12: 40609 | AC12: 40603 | AE12: Prof Afolabi Bamgboye | AF12: Prof. Olusola Ayeni | AH12: =COUNTA(AE12:AG12) -> 2 | AI12: Home | AJ12: Host | AL12: Yes | AM12: No | AO12: Academic | AP12: Lecturer | AQ12: Professor | AR12: Yes | AT12: UNIVERSITY OF IBADAN | AU12: 0000-0002-0675-2110 | AW12: 40634 | AX12: 40878 | AY12: Yes | BD12: 41456 | BE12: Yes | BF12: 41704 | BG12: Yes | BK12: 41671 | BL12: Completed | BM12: =DATEDIF(AW12,BK12, "M")+1 -> 35 | BN12: =DATEDIF(AX12,BK12, "M")+1 -> 27 | BO12: Levels, Trends and Differentials in Under-five Mortality in Nigeria (1990-2008) | BP12: 18 | BQ12: 14 | BR12: 117 | BS12: 4 | BT12: 2 | BU12: 7 | BV12: 6 | BW12: No | BX12: No | CC12: No | CF12: 0 | CG12: 2 | CI12: NF
A13: 12 | B13: C1/012 | C13: Mphatso | D13: Steve Wilbes | E13: Kamndaya | F13: Male | G13: 1 | H13: Malawi | I13: University of Malawi | J13: Mathematics and Statistics | L13: University of the Witwatersrand | M13: No | O13: Married | P13: Married | Q13: Married | R13: mkamndaya@cartafrica.org | S13: kamndayam@yahoo.com | T13: +265999851477 | U13: MSc Mathematical Statistics | V13: 27918 | W13: Modeling indoor air pollution to improve health delivery systems and public health in Malawi | X13: Field | Y13: No | Z13: Primary | AA13: 18 | AB13: 40612 | AC13: 40603 | AE13: Lawrence N.M. Kazembe | AF13: Dr. Liz Thomas | AH13: =COUNTA(AE13:AG13) -> 2 | AI13: Home | AJ13: Host | AL13: Yes | AM13: No | AO13: Academic | AP13: Lecturer | AQ13: Associate Professor | AR13: Yes | AT13: UNIVERSITY OF MALAWI | AU13: 0000-0002-7597-3339 | AW13: 40634 | AX13: 40878 | AY13: Yes | BB13: 41193 | BC13: Multilevel analysis of determinants of HIV- related sexual risks-taking and decision making among youths in urban informal settlements in Malawi and South Africa | BD13: 41456 | BE13: Yes | BF13: 41705 | BG13: Yes | BK13: 42460 | BL13: Completed | BM13: =DATEDIF(AW13,BK13, "M")+1 -> 60 | BN13: =DATEDIF(AX13,BK13, "M")+1 -> 52 | BP13: 0 | BQ13: 5 | BR13: 10 | BS13: 5 | BT13: 0 | BU13: 0 | BV13: 0 | BW13: No | BX13: No | CC13: No | CF13: 1 | CG13: 2 | CI13: NF
A14: 13 | B14: C1/013 | C14: Esther | D14: Clyde | E14: Nabakwe | F14: Female | G14: 1 | H14: Kenya | I14: Moi University | J14: Pediatrics & Child health | L14: Moi University | M14: Yes | O14: Single | P14: Single | Q14: Single | R14: nabakwe@cartafrica.org | S14: echirwa@chanco.unima.mw edkwalira@yahoo.com | U14: M.Med Paediatrics | V14: 23063 | W14: Socio-cultural and economic determinants of HIV mothers' knowledge, attitude and practise of current WHO infant feeding policy and the impact on infants' outcome | X14: Field | Y14: No | Z14: Primary | AA14: 25 | AB14: 40605 | AC14: 40603 | AE14: Prof Joshua Akong’a | AF14: Dr. Grace Ettyang | AH14: =COUNTA(AE14:AG14) -> 2 | AI14: Home | AJ14: Host | AL14: Yes | AM14: Yes | AO14: Academic | AQ14: Senior Lecturer | AT14: MOI UNIVERSITY | AU14: 0000-0002-0401-3373 | AW14: 40634 | AX14: 40878 | AY14: Yes | AZ14: 40665 | BA14: 40727 | BD14: 41456 | BE14: Yes | BF14: 41706 | BG14: Yes | BK14: 43699 | BL14: Completed | BM14: =DATEDIF(AW14,BK14, "M")+1 -> 101 | BN14: =DATEDIF(AX14,BK14, "M")+1 -> 93 | BO14: Sex and young people in urban slums: Exploring the material deprivation and sexual risk nexus in Malawi and South Africa | BP14: 4 | BQ14: 4 | BR14: 2 | BS14: 0 | BT14: 0 | BU14: 0 | BV14: 0 | BW14: No | BX14: No | CC14: No | CF14: 3 | CG14: 3 | CI14: NF
A15: 14 | B15: C1/014 | C15: Nicole | E15: De Wet | F15: Female | G15: 1 | H15: South Africa | I15: University of the Witwatersrand | J15: Demography | K15: Demography and Population Studies | L15: University of the Witwatersrand | M15: Yes | N15: 0211542Y | O15: Single | P15: Married | Q15: Single | R15: ndewet@cartafrica.org | S15: nicole.dewet@wits.ac.za Nic_dewet@yahoo.com | U15: Master of Arts Demography and Population Studies | V15: 30815 | W15: Domestic Violence and child health outcomes: An investigation into the relationship between frequency of abuse and negative child health outcomes in two African countries. | X15: Field | Y15: No | Z15: Primary | AA15: 22.5 | AB15: 40605 | AC15: 40603 | AE15: Prof Clifford Odimegwu | AH15: =COUNTA(AE15:AG15) -> 1 | AI15: Home | AL15: No | AO15: Academic | AP15: Tutor | AQ15: Associate Professor | AR15: Yes | AS15: Assistant Dean for Postgraduate Studies, Faculty of Humanities | AT15: UNIVERSITY OF THE WITWATERSRAND | AU15: 0000-0001-5750-2851 | AW15: 40634 | AX15: 40878 | AY15: Yes | BD15: 41456 | BE15: Yes | BF15: 41707 | BG15: Yes | BK15: 41608 | BL15: Completed | BM15: =DATEDIF(AW15,BK15, "M")+1 -> 32 | BN15: =DATEDIF(AX15,BK15, "M")+1 -> 24 | BP15: 0 | BQ15: 2 | BR15: 56 | BS15: 4 | BT15: 6 | BU15: 11 | BV15: 7 | BW15: No | BX15: No | CC15: No | CF15: 0 | CG15: 0 | CI15: NF
A16: 15 | B16: C1/015 | C16: Kennedy | D16: S.Naviava | E16: Otwombe | F16: Male | G16: 1 | H16: South Africa | I16: University of the Witwatersrand | J16: Epidemiology & Medical Biostatistics | K16: Perinatal HIV Research Unit, Dept. Data and Statistics | L16: University of the Witwatersrand | M16: Yes | O16: Married | P16: Married | Q16: Married | R16: otwombek@phru.co.za | S16: otwombek@phru.co.za | U16: M.Sc Mathematical statistics | V16: 26801 | W16: Use of frailty modeling with arbitrary censoring in determining predictors of mortality for a Clinical researchized HIV positive population in South Africa | X16: Clinical research | Y16: No | Z16: Secondary | AA16: 21 | AB16: 40638 | AC16: 40603 | AE16: Dr. Tobias Chirwa | AF16: Dr. Guy de Bruyn | AH16: =COUNTA(AE16:AG16) -> 2 | AI16: Home | AJ16: Home | AL16: Yes | AM16: No | AO16: Other | AP16: Senior Statistician | AQ16: Associate Professor | AR16: Yes | AT16: UNIVERSITY OF THE WITWATERSRAND | AU16: 0000-0002-7433-4383 | AW16: 40634 | AX16: 40878 | AY16: Yes | BD16: 41456 | BE16: Yes | BF16: 41708 | BG16: Yes | BK16: 43285 | BL16: Completed | BM16: =DATEDIF(AW16,BK16, "M")+1 -> 88 | BN16: =DATEDIF(AX16,BK16, "M")+1 -> 80 | BP16: 8 | BQ16: 45 | BR16: 55 | BS16: 5 | BT16: 2 | BU16: 0 | BV16: 0 | BW16: No | BX16: No | CC16: No | CF16: 2 | CG16: 2 | CI16: NF
A17: 16 | B17: C1/016 | C17: Peter | D17: Suriwakenda | E17: Nyasulu | F17: Male | G17: 1 | H17: Malawi | I17: University of the Witwatersrand | J17: Epidemiology & Medical Biostatistics | K17: Division of Epidemiology & Medical Biostatistics | L17: University of the Witwatersrand | M17: Yes | P17: Married | R17: pnyasulu@cartafrica.org | S17: Peter.Nyasulu@wits.ac.za | U17: M.Sc (Medicine) | V17: 25201 | W17: Surveillance of antimicrobial susceptibility patterns among pathogens isolated in public sector Clinical researchs associated with academic institutions, South Africa during a 5 year period 2005-2009 | X17: Clinical research - Retrospective | Y17: yes | Z17: Secondary | AA17: 11 | AB17: 40605 | AC17: 40603 | AE17: Prof Jill Murray | AF17: Prof. Hendrik J. Koornhof | AG17: Dr. Olga Perovic | AH17: =COUNTA(AE17:AG17) -> 3 | AI17: Home | AJ17: Home | AK17: Home | AL17: Yes | AM17: No | AN17: No | AO17: Academic | AQ17: Associate Professor | AR17: Yes | AT17: STELLENBOSCH UNIVERSITY | AU17: 0000-0003-2757-0663 | AW17: 40634 | AX17: 40878 | AY17: Yes | BD17: 41456 | BE17: Yes | BF17: 41709 | BG17: Yes | BK17: 41912 | BL17: Completed | BM17: =DATEDIF(AW17,BK17, "M")+1 -> 42 | BN17: =DATEDIF(AX17,BK17, "M")+1 -> 34 | BP17: 3 | BQ17: 10 | BR17: 77 | BS17: 4 | BT17: 10 | BU17: 6 | BV17: 9 | BW17: No | BX17: No | CC17: No | CF17: NF | CG17: NF | CI17: NF
A18: 17 | B18: C1/017 | C18: Rose | D18: Okoyo | E18: Opiyo | F18: Female | G18: 1 | H18: Kenya | I18: University of Nairobi | J18: Nutrition | K18: Food Science, Nutrition and Technology | L18: University of Nairobi | M18: Yes | N18: A80/82301/2011 | O18: Married | P18: Married | Q18: Married | R18: ropiyo@cartafrica.org | S18: roseopiyo@uonbi.ac.ke roseopiyo04@yahoo.co.uk | T18: +254 722473122 | U18: Msc Applied Human Nutrition | V18: 22992 | W18: Effect of Omega-3 Fatty Acids (Fish Oil) Supplementation along with Diet on Depression and Nutrition Status of HIV-Seropositive and HIV-Seronegative Pregnant Mothers among Low-income Urban Population in Nairobi | X18: Clinical research - RCT | Y18: yes | Z18: Primary | AA18: 17 | AB18: 40801 | AC18: 40603 | AE18: Prof. Wambui Kogi-Makau | AF18: Prof. Koigi R. Kamau | AG18: Dr. Anne Obondo | AH18: =COUNTA(AE18:AG18) -> 3 | AI18: Home | AJ18: Home | AK18: Home | AL18: Yes | AM18: No | AN18: No | AO18: Academic | AP18: Lecturer | AQ18: Senior Lecturer | AR18: Yes | AS18: Member of College of Health Sciences, University of Nairobi Committee on Guidelines for PhD Equivalent Qualifications for Clinicians. | AT18: UNIVERSITY OF NAIROBI | AU18: 0000-0003-1885-9991 | AW18: 40634 | AX18: 40878 | AY18: Yes | BC18: Effect of fish oil Omega- 3 fatty acids on reduction of depressive symptoms among HIV - seropositive pregnant women | BD18: 41456 | BE18: Yes | BF18: 41710 | BG18: Yes | BK18: 42277 | BL18: Completed | BM18: =DATEDIF(AW18,BK18, "M")+1 -> 54 | BN18: =DATEDIF(AX18,BK18, "M")+1 -> 46 | BO18: Effect of fish oil Omega- 3 fatty acids on reduction of depressive symptoms among HIV - seropositive pregnant women | BQ18: 3 | BR18: 8 | BS18: 1 | BT18: 1 | BU18: 1 | BV18: 0 | BW18: No | BX18: No | CC18: No | CF18: 2 | CG18: 2 | CI18: NF
A19: 18 | B19: C1/018 | C19: Sunday | D19: Adepoju | E19: Adedini | F19: Male | G19: 1 | H19: Nigeria | I19: Obafemi Awolowo University | J19: Demography and Population Studies | K19: Demography and Population Studies | L19: University of the Witwatersrand | M19: No | N19: 560454 | O19: Married | P19: Married | Q19: Married | R19: sadedini@cartafrica.org | S19: sunday.adedini@gmail.com adedinisunday@yahoo.com | T19: +234-803 397 7498 | U19: M.Sc Demography and Social Statistics | V19: 27511 | W19: Multilevel Analysis of Determinants of Infant and Child Mortality in West Africa | X19: Field | Y19: No | Z19: Secondary | AA19: 13 | AB19: 40582 | AC19: 40603 | AE19: Prof Clifford Odimegwu | AF19: Dr. Samson Bamiwuye | AH19: =COUNTA(AE19:AG19) -> 2 | AI19: Host | AJ19: Home | AL19: Yes | AM19: Yes | AO19: Academic | AP19: Lecturer | AQ19: Professor | AR19: Yes | AS19: Head Demographer; Head of Demography and Social Statistics (2021) | AT19: FEDERAL UNIVERSITY, OYE-EKITI (2020) | AU19: 0000-0003-0378-1941 | AW19: 40634 | AX19: 40878 | AY19: Yes | BD19: 41456 | BE19: Yes | BF19: 41711 | BG19: Yes | BK19: 41334 | BL19: Completed | BM19: =DATEDIF(AW19,BK19, "M")+1 -> 24 | BN19: =DATEDIF(AX19,BK19, "M")+1 -> 16 | BP19: NF | BQ19: 4 | BR19: 43 | BS19: 6 | BT19: 4 | BU19: 6 | BV19: 6 | BW19: No | BX19: No | CC19: No | CF19: 3 | CG19: 3 | CI19: NF
A20: 19 | B20: C1/019 | C20: Sulaimon | D20: Taiwo | E20: Adedokun | F20: Male | G20: 1 | H20: Nigeria | I20: Obafemi Awolowo University | J20: Demography and Social Statistics | K20: Demography and Social Statistics | L20: Obafemi Awolowo University | M20: Yes | O20: Married | P20: Married | Q20: Married | R20: sadedokun@cartafrica.org | S20: adedokunsulait@gmail.com | T20: +2348051398276 | U20: M.Sc Demography and Social Statistics | V20: 26644 | W20: Maternal and Socio-demographic Correlates of Under-five Mortality in Yobe State, Nigeria | X20: Field | Y20: No | Z20: Secondary | AA20: 21.5 | AB20: 40605 | AC20: 40603 | AE20: Ogunjuyigbe Peter Olasupo | AH20: =COUNTA(AE20:AG20) -> 1 | AI20: Home | AL20: Yes | AO20: Academic | AP20: Lecturer II | AQ20: Associate Professor | AR20: Yes | AT20: OBAFEMI AWOLOWO UNIVERSITY | AU20: 0000-0003-0021-8045 | AW20: 40634 | AX20: 40878 | AY20: Yes | BB20: 41225 | BC20: Comparative analysis of the factors accounting for under-five mortality differentials in North East and South West of Nigeria | BD20: 41456 | BE20: Yes | BF20: 42064 | BG20: No | BK20: 41395 | BL20: Completed | BM20: =DATEDIF(AW20,BK20, "M")+1 -> 26 | BN20: =DATEDIF(AX20,BK20, "M")+1 -> 18 | BO20: Comparative analysis of the factors accounting for under-five mortality differentials in North East and South West of Nigeria | BR20: 12 | BS20: 0 | BT20: 0 | BU20: 4 | BV20: 1 | BW20: No | BX20: No | CC20: No | CF20: 3 | CG20: 5 | CI20: NF
A21: 20 | B21: C1/020 | C21: Sulaimon | D21: Atolagbe | E21: Afolabi | F21: Male | G21: 1 | H21: Nigeria | I21: AGINCOURT | J21: Demography & Population Studies | K21: Demography & Population Studies | L21: University of the Witwatersrand | M21: No | N21: 0607789e | P21: Married | R21: safolabi@cartafrica.org | S21: afolaborn@gmail.com | T21: +2771718311 | U21: MA in Demography and Population studies | V21: 28744 | W21: License to move: a longitudinal study of migration and its relation to HIV and TB in high mortality post-apartheid South Africa. | X21: Field | Y21: yes | Z21: Primary | AA21: 12 | AB21: 40609 | AC21: 40603 | AE21: Dr. Mark Collinson | AF21: Prof. Philippe Bocquier | AH21: =COUNTA(AE21:AG21) -> 2 | AI21: Home | AJ21: Host | AL21: Yes | AM21: No | AO21: Other | AQ21: Lead Data Scientist | AT21: UNIVERSITY OF THE WITWATERSRAND | AU21: 0000-0001-9382-6386 | AW21: 40634 | AX21: 40878 | AY21: Yes | BD21: 41456 | BE21: Yes | BF21: 41712 | BG21: Yes | BK21: 43073 | BL21: Completed | BM21: =DATEDIF(AW21,BK21, "M")+1 -> 81 | BN21: =DATEDIF(AX21,BK21, "M")+1 -> 73 | BP21: 1 | BQ21: 8 | BR21: 3 | BS21: 0 | BT21: 0 | BU21: 0 | BV21: 0 | BW21: No | BX21: No | CC21: No | CF21: NF | CG21: NF | CI21: NF | CJ21: Deceased 15/02/2021
A22: 22 | B22: C1/022 | C22: Theresa | D22: Njeri | E22: Kinyari | F22: Female | G22: 1 | H22: Kenya | I22: University of Nairobi | N22: NF | O22: NF | P22: NF | Q22: NF | AC22: 40603 | AD22: 40865 | AH22: =COUNTA(AE22:AG22) -> 0 | AW22: 40634 | BL22: Terminated | BM22: Terminated | BW22: No | CI22: NF
A23: 23 | B23: C1/023 | C23: Peter | D23: Mwamba | E23: Maturi | F23: Male | G23: 1 | H23: Kenya | I23: University of Nairobi | L23: University of Nairobi | M23: Yes | N23: NF | O23: NF | P23: NF | Q23: NF | AC23: 40603 | AD23: 42613 | AH23: =COUNTA(AE23:AG23) -> 0 | AW23: 40634 | BL23: Terminated | BM23: Terminated | BW23: No | CI23: NF
A24: 24 | B24: C1/024 | C24: Jaclkline | D24: Halima | E24: Mgumia | F24: Female | G24: 1 | H24: Tanzania | I24: University of Dar es Salaam | N24: NF | O24: NF | P24: NF | Q24: NF | AC24: 40603 | AD24: 41274 | AH24: =COUNTA(AE24:AG24) -> 0 | AW24: 40634 | BL24: Terminated | BM24: Terminated | BW24: No | CI24: NF
A25: 26 | B25: C2/001 | C25: Adebolajo | E25: Adeyemo | F25: Male | G25: 2 | H25: Nigeria | I25: University of Ibadan | J25: Epidemiology | L25: University of Ibadan | M25: Yes | O25: Married | P25: Married | R25: aadeyemo@cartafrica.org | S25: adebolajo@hotmail.com | U25: M.Sc Immunology | V25: 27062 | W25: Genetic epidemiology in Nigeria | X25: Field | Y25: yes | Z25: Primary | AA25: 13.5 | AB25: 40924 | AC25: 40969 | AE25: Prof. Odunayo Moronfoluwa Oluwatosin | AF25: Prof. Omotade Olayemi Olufemi-Julius | AH25: =COUNTA(AE25:AG25) -> 2 | AI25: Home | AJ25: Home | AL25: Yes | AM25: No | AO25: Academic | AP25: Assistant lecturer | AQ25: Senior Medical Research Fellow | AR25: Yes | AT25: UNIVERSITY OF IBADAN | AU25: 0000-0002-7486-5758 | AW25: 40969 | AX25: 41214 | AY25: Yes | BD25: 41852 | BE25: Yes | BF25: 42064 | BG25: Yes | BK25: 45183 | BL25: Completed | BM25: =DATEDIF(AW25,BK25, "M")+1 -> 139 | BN25: =DATEDIF(AX25,BK25, "M")+1 -> 131 | BP25: 1 | BQ25: 14 | BR25: 0 | BS25: 1 | BT25: 0 | BU25: 0 | BV25: 0 | BW25: No | BX25: 0 | CC25: No | CF25: 2 | CG25: NF | CI25: NF
A26: 27 | B26: C2/002 | C26: Alinane Linda | E26: Nyondo-Mipando | F26: Female | G26: 2 | H26: Malawi | I26: University of Malawi | J26: Health Systems and Policy | K26: Health Systems and Policy | L26: University of the Malawi | M26: Yes | N26: - | O26: Married | P26: Married | Q26: Married | R26: alinda@cartafrica.org | S26: lindaalinane@gmail.com | T26: +265 999 44 1212 | U26: Master of Nursing (Community Health) Online | V26: 28103 | W26: The feasibility of male involvement in Prevention of Mother to Child Transmission of HIV services in Malawi. | X26: Field | Y26: No | Z26: Primary | AA26: 18 | AB26: 40917 | AC26: 40969 | AE26: Dr. Angela Chimwaza | AF26: Dr. Adamson Muula | AH26: =COUNTA(AE26:AG26) -> 2 | AI26: Home | AJ26: Home | AL26: Yes | AM26: Yes | AO26: Academic | AP26: Project Coordinator | AQ26: Associate Professor | AR26: Yes | AS26: Deputy Dean, SPH and coordinator of Postgraduate Programs, School of Governance | AT26: UNIVERSITY OF LIVERPOOL, DEPARTMENT OF WOMEN'S AND CHILDREN'S HEALTH (2022) | AU26: 0000-0002-3572-3810 | AW26: 40969 | AX26: 41214 | AY26: Yes | BD26: 41852 | BE26: Yes | BF26: 42064 | BG26: Yes | BK26: 42460 | BL26: Completed | BM26: =DATEDIF(AW26,BK26, "M")+1 -> 49 | BN26: =DATEDIF(AX26,BK26, "M")+1 -> 41 | BP26: 0 | BQ26: 4 | BR26: 36 | BS26: 1 | BT26: 0 | BU26: 1 | BV26: 1 | BW26: No | BX26: 0 | CC26: No | CF26: 2 | CG26: 2 | CI26: FF
A27: 28 | B27: C2/003 | C27: Austin | D27: Henderson | E27: Mtethiwa | F27: Male | G27: 2 | H27: Malawi | I27: University of Malawi | J27: Environmental Sciences | L27: University of the Malawi | M27: Yes | P27: NF | R27: amtethiwa@cartafrica.org | T27: +265888316331 | U27: M. Sc Limnology & Wetland Ecosystems | V27: 26796 | W27: Contribution of domestic waste water treatment plants to proliferation of schistosomiasis and pollution of aquatic resources and ability herbaceous plants for waste water treatment | X27: Field | Y27: yes | Z27: Primary | AA27: 12 | AB27: 40977 | AC27: 40969 | AE27: Wilson Mandala | AF27: Dr. Lucy Namkinga | AH27: =COUNTA(AE27:AG27) -> 2 | AI27: Home | AJ27: Other | AL27: Yes | AM27: Yes | AO27: Academic | AP27: Lecturer | AQ27: Associate Professor | AR27: Yes | AT27: UNIVERSITY OF MALAWI | AU27: 0000-0003-0793-5186 | AW27: 40969 | AX27: 41214 | AY27: Yes | BD27: 41852 | BE27: Yes | BF27: 42064 | BG27: Yes | BK27: 42704 | BL27: Completed | BM27: =DATEDIF(AW27,BK27, "M")+1 -> 57 | BN27: =DATEDIF(AX27,BK27, "M")+1 -> 49 | BP27: 2 | BQ27: 1 | BR27: 9 | BS27: 1 | BT27: 1 | BU27: 0 | BV27: 0 | BW27: No | BX27: 0 | CC27: No | CF27: NF | CG27: NF | CI27: CARNEGIE 2
A28: 29 | B28: C2/004 | C28: Diana | D28: - | E28: Menya | F28: Female | G28: 2 | H28: Kenya | I28: Moi University | J28: Medical Epidemiology | K28: Library | L28: Moi University | M28: Yes | O28: Married | P28: Married | R28: dmenya@cartafrica.org | S28: dianamenya@gmail.com | T28: +254 720352579/+254 733777500 | U28: MSc. Clinical Epidemiology | V28: 27531 | X28: Clinical research | Y28: unkown | Z28: Primary | AB28: 41334 | AC28: 40969 | AE28: Prof. Odipo Osano | AF28: Prof Rafael Carel | AH28: =COUNTA(AE28:AG28) -> 2 | AI28: Other | AJ28: Other | AL28: No | AM28: No | AO28: Academic | AP28: Senior Lecturer | AQ28: Associate Professor | AR28: Yes | AT28: MOI UNIVERSITY | AU28: 000 0000337081871 | AW28: 40969 | AX28: 41214 | AY28: Yes | BD28: 41852 | BE28: Yes | BF28: 42064 | BG28: Yes | BK28: 42704 | BL28: Completed | BM28: =DATEDIF(AW28,BK28, "M")+1 -> 57 | BN28: =DATEDIF(AX28,BK28, "M")+1 -> 49 | BO28: Behavioral, Nutritional and Environmental Factors associated with Esophageal Cancer in western Kenya | BP28: 8 | BQ28: 19 | BR28: 43 | BS28: 2 | BT28: 2 | BU28: 1 | BV28: 0 | BW28: No | BX28: 0 | CC28: No | CF28: 2 | CG28: 2 | CH28: 2 | CI28: NF
A29: 30 | B29: C2/005 | C29: Evaline | E29: Mcharo | F29: Female | G29: 2 | H29: Tanzania | I29: University of Dar es Salaam | J29: Epidemiology | K29: Geography | L29: University of Nairobi | M29: No | O29: Single | P29: Single | Q29: Single | R29: emcharo@cartafrica.org | S29: mcharoevaline@gmail.com; evalinemcharo@yahoo.co.uk | U29: MA in demography (online) | V29: 29064 | W29: Socioeconomic determinants of unsafe abortion and its implication to women in Tanzania. | X29: Field | Y29: No | Z29: Primary | AA29: 21.5 | AB29: 40946 | AC29: 40969 | AE29: Dr. Lawrence Ikamari | AF29: Dr. Alfred Agwanda Otieno | AH29: =COUNTA(AE29:AG29) -> 2 | AI29: Host | AJ29: Host | AL29: Yes | AM29: Yes | AO29: Researcher | AP29: Assistant Lecturer | AQ29: Lecturer | AR29: Yes | AT29: UNIVERSITY OF DAR ES SALAAM | AW29: 40969 | AX29: 41214 | AY29: Yes | BD29: 41852 | BE29: Yes | BF29: 42064 | BG29: Yes | BK29: 42735 | BL29: Completed | BM29: =DATEDIF(AW29,BK29, "M")+1 -> 58 | BN29: =DATEDIF(AX29,BK29, "M")+1 -> 50 | BP29: NF | BQ29: 0 | BR29: 1 | BS29: 0 | BT29: 0 | BU29: 0 | BV29: 1 | BW29: No | BX29: 0 | CC29: No | CF29: NF | CG29: NF | CI29: WT
A30: 31 | B30: C2/006 | C30: Stephen | D30: Ojiambo | E30: Wandera | F30: Male | G30: 2 | H30: Uganda | I30: Makerere University | J30: Epidemiology | K30: Department of Population Studies | L30: Makerere University | M30: Yes | O30: Married | P30: married | Q30: Married | R30: swandera@cartafrica.org | S30: swandera@gmail.com | T30: +256774976879 | U30: M.Sc Population & Reproductive Health | V30: 30697 | W30: Intergenerational Support and Health of the Ageing Population In Rural Uganda | X30: Field | Y30: No | Z30: Primary | AA30: 2 | AB30: 40946 | AC30: 40969 | AE30: Dr. James Ntozi | AF30: Dr. Betty Kwagala | AH30: =COUNTA(AE30:AG30) -> 2 | AI30: Home | AJ30: Home | AL30: Yes | AM30: No | AO30: Academic | AP30: Assistant Lecturer | AQ30: Senior Lecturer | AR30: Yes | AS30: Head of Department | AT30: MAKERERE UNIVERISTY | AU30: 0000-0002-5617-0274 | AW30: 40969 | AX30: 41214 | AY30: Yes | BC30: Disaparities in health and access to healthcare among older persons in Uganda | BD30: 41852 | BE30: Yes | BF30: 42064 | BG30: Yes | BK30: 42460 | BL30: Completed | BM30: =DATEDIF(AW30,BK30, "M")+1 -> 49 | BN30: =DATEDIF(AX30,BK30, "M")+1 -> 41 | BO30: Disaparities in health and access to healthcare among older persons in Uganda | BP30: 0 | BQ30: 10 | BR30: 16 | BS30: 6 | BT30: 2 | BU30: 2 | BV30: 0 | BW30: No | BX30: 0 | CC30: No | CF30: 2 | CG30: 3 | CI30: WT
A31: 32 | B31: C2/007 | C31: Adeniyi | D31: Francis | E31: Fagbamigbe | F31: Male | G31: 2 | H31: Nigeria | I31: University of Ibadan | J31: BIOSTATISTICS | K31: EPIDEMIOLOGY AND MEDICAL STATISTICS | L31: University of Ibadan | M31: Yes | N31: 152419 | P31: Married | R31: fadeniyi@cartafrica.org | S31: franstel74@yahoo.com | T31: +2348061348165 | U31: Masters in medical statistics | V31: 27076 | W31: Modeling association between bivariate censored outcomes: a case study of bipolar disorder | X31: Field | Y31: No | Z31: Primary | AA31: 4 | AB31: 40987 | AC31: 40969 | AE31: Prof. Elijah Afolabi Bamgboye | AH31: =COUNTA(AE31:AG31) -> 1 | AI31: Home | AL31: Yes | AO31: Academic | AP31: Lecturer II | AQ31: Professor | AR31: Yes | AT31: UNIVERSITY OF IBADAN | AU31: 0000-0001-9184-8258 | AW31: 40969 | AX31: 41214 | AY31: Yes | BD31: 41852 | BE31: Yes | BF31: 42064 | BG31: Yes | BK31: 41729 | BL31: Completed | BM31: =DATEDIF(AW31,BK31, "M")+1 -> 25 | BN31: =DATEDIF(AX31,BK31, "M")+1 -> 17 | BP31: 6 | BQ31: 6 | BR31: 93 | BS31: 8 | BT31: 4 | BU31: 18 | BV31: 4 | BW31: No | BX31: 0 | CC31: No | CF31: NF | CG31: 2 | CI31: MAC
A32: 33 | B32: C2/008 | C32: Tumwine | E32: Gabriel | F32: Male | G32: 2 | H32: Uganda | I32: Makerere University | J32: Epidemiology | L32: Makerere University | M32: Yes | P32: NF | R32: gtumwine@cartafrica.org | S32: gtumwine@vetmed.mak.ac.ug; tumwinegabriel@gmail.com | T32: +256782194819 | U32: M.Sc Molecular Biology | V32: 29825 | W32: Malaria and filariasis co-infection during pregnancy in high malaria transmission areas of Uganda: Impacts on pregnancy outcomes, immune response and antifolates effects | X32: Clinical research | Y32: yes | Z32: Primary | AA32: 18.5 | AB32: 40933 | AC32: 40969 | AE32: Dr. Enock Matovu | AF32: Dr. Jean Langhorne | AH32: =COUNTA(AE32:AG32) -> 2 | AI32: Home | AJ32: Other | AL32: Yes | AM32: No | AO32: Academic | AP32: Teaching Assistant | AT32: MAKERERE UNIVERSITY | AU32: 0000-0003-3338-5333 | AW32: 40969 | AX32: 41214 | AY32: Yes | BD32: 41852 | BE32: Yes | BF32: 42064 | BG32: Yes | BL32: In progress | BP32: 1 | BQ32: 9 | BR32: 0 | BS32: 1 | BT32: 0 | BU32: 0 | BV32: 0 | BW32: No | BX32: 0 | CC32: No | CF32: 3 | CG32: NF | CI32: CARNEGIE 2
A33: 34 | B33: C2/009 | C33: Herbert | D33: Hudson | E33: Longwe | F33: Male | G33: 2 | H33: Malawi | I33: University of Malawi | J33: Epidemiology | K33: Department of Population Studies | L33: University of the Malawi | M33: Yes | O33: Married | P33: Married | Q33: Married | R33: hlongwe@cartafrica.org | S33: Herbert.longwe@gmail.com, hlongwe@medcol.mw | U33: Master of Philosophy (Tropical Medicine). | V33: 29122 | W33: Investigating the effect of daily cotrimoxazole prophylaxis on the acquisition of malaria specific immunity in HIV exposed children and HIV infected children | X33: Clinical research | Y33: yes | Z33: Primary | AA33: 5.5 | AB33: 40961 | AC33: 40969 | AE33: Dr. Wilson Mandala | AF33: Dr. Adam Cunningham | AG33: Cal MacLennan | AH33: =COUNTA(AE33:AG33) -> 3 | AI33: Home | AJ33: Other | AL33: Yes | AM33: No | AP33: Research Scientist | AQ33: Deputy Director Laboratory Support, ICAP at Columbia University | AR33: Yes | AT33: COLUMBIA UNIVERSITY, SOUTH AFRICA | AU33: 0000-0002-2496-896X | AW33: 40969 | AX33: 41214 | AY33: Yes | BC33: Efect of daily contrimoxazole prophylaxis on naturally acquired plasmodium falciparum -Specific Immune Responses in HIV - exposed uninfected Malawian Children | BD33: 41852 | BE33: Yes | BF33: 42064 | BG33: Yes | BK33: 42185 | BL33: Completed | BM33: =DATEDIF(AW33,BK33, "M")+1 -> 40 | BN33: =DATEDIF(AX33,BK33, "M")+1 -> 32 | BO33: Efect of daily contrimoxazole prophylaxis on naturally acquired plasmodium falciparum -Specific Immune Responses in HIV - exposed uninfected Malawian Children | BP33: 3 | BQ33: 1 | BR33: 13 | BS33: 3 | BT33: 0 | BU33: 0 | BV33: 0 | BW33: No | BX33: 0 | CC33: No | CF33: 1 | CG33: 2 | CI33: NF
A34: 35 | B34: C2/010 | C34: Joseph | D34: Maurice | E34: Mutisya | F34: Male | G34: 2 | H34: Kenya | I34: APHRC | J34: Public Health | K34: Education Research Program | L34: University of the Witwatersrand | M34: No | O34: Married | P34: Married | Q34: Married | R34: jmutisya@cartafrica.org | S34: mmutisya@aphrc.org mmutisya@ymail.com | T34: +25421987850 | U34: MSC (Population Based Epidemiology) | V34: 29322 | W34: Knowledge, Attitude and Beliefs on Stigma and Discrimination among people living with HIV & AIDS in Kenya: Individual and Community Level Effects | X34: Field | Y34: yes | Z34: Primary | AA34: 2 | AB34: 40987 | AC34: 40969 | AE34: Dr. Moses Ngware | AF34: Dr. Caroline Kabiru | AG34: Dr. Kandala Ngianga | AH34: =COUNTA(AE34:AG34) -> 3 | AI34: Home | AJ34: Home | AK34: Other | AL34: Yes | AM34: Yes | AN34: No | AO34: Researcher | AP34: Data Analyst | AQ34: Director Research at Zizi Afrique | AR34: Yes | AT34: ZIZI AFRIQUE FOUNDATION, KENYA (2022) | AU34: 0000-0001-5981-6344 | AW34: 40973 | AX34: 41225 | AY34: Yes | AZ34: 41740 | BB34: 41880 | BD34: 41852 | BE34: Yes | BF34: 42064 | BG34: Yes | BH34: 42859 | BI34: 42859 | BJ34: 43047 | BK34: 43438 | BL34: Completed | BM34: =DATEDIF(AW34,BK34, "M")+1 -> 81 | BN34: =DATEDIF(AX34,BK34, "M")+1 -> 73 | BO34: Household food security, child Nutrition, and education: A longitudinal Analysis in Two urban informal Settlements in Kenya | BP34: 6 | BQ34: 20 | BR34: 7 | BS34: 1 | BT34: 2 | BU34: 0 | BV34: 0 | BW34: No | BX34: 0 | CC34: No | CF34: 1 | CG34: 3 | CI34: CARNEGIE 2
A35: 36 | B35: C2/011 | C35: Njuguna | D35: John | E35: Njenga | F35: Male | G35: 2 | H35: Kenya | I35: University of Nairobi | J35: Demography & Social statistics | K35: Population Studies and Research Institute (PSRI | L35: University of Nairobi | M35: Yes | P35: NF | R35: jnjega@cartafrica.org | T35: +254721473921 | U35: NF | V35: 26369 | W35: Determinants of Active Life Expectancy among Adult HIV/AIDS Patients in Kenya | X35: Field | Y35: No | Z35: Primary | AA35: 15 | AB35: 40959 | AC35: 40969 | AE35: Dr. Lawrence Ikamari | AF35: Dr. Murungaru Kimani | AH35: =COUNTA(AE35:AG35) -> 2 | AI35: Home | AJ35: Home | AL35: Yes | AM35: No | AO35: Academic | AT35: NF | AU35: 0000-0001-7130-1626 | AW35: 40969 | AX35: 41214 | AY35: Yes | BD35: 41852 | BE35: Yes | BF35: 42064 | BG35: Yes | BK35: 42735 | BL35: Completed | BM35: =DATEDIF(AW35,BK35, "M")+1 -> 58 | BN35: =DATEDIF(AX35,BK35, "M")+1 -> 50 | BP35: 1 | BQ35: 6 | BR35: 6 | BS35: 0 | BT35: 0 | BU35: 0 | BV35: 0 | BW35: No | BX35: 0 | CC35: No | CF35: NF | CG35: NF | CI35: WT
A36: 37 | B36: C2/012 | C36: Mary | D36: Oluwafunke | E36: Obiyan | F36: Female | G36: 2 | H36: Nigeria | I36: Obafemi Awolowo University | J36: Demography | K36: Demography and Social Statistics | L36: Obafemi Awolowo University | M36: Yes | O36: Married | P36: Married | Q36: Married | R36: mobiyan@cartafrica.org | S36: maryobiyan@gmail.com | T36: +2348038161303 | U36: M.Sc Demography and Social Statistics | V36: 29380 | W36: Wealth Quintile and Fertility Differentials among Households in Nigeria | X36: Field | Y36: No | Z36: Primary | AA36: 11 | AB36: 40961 | AC36: 40969 | AE36: Prof. Peter O. Ogunjuyigbe | AF36: Ambrose Akinlo | AH36: =COUNTA(AE36:AG36) -> 2 | AI36: Home | AL36: Yes | AO36: Academic | AP36: Lecturer II | AQ36: Senior Lecturer | AR36: Yes | AT36: OBAFEMI AWOLOWO UNIVERSITY | AU36: 0000-0003-3583-0138 | AW36: 40969 | AX36: 41214 | AY36: Yes | BD36: 41852 | BE36: Yes | BF36: 42064 | BG36: Yes | BK36: 41729 | BL36: Completed | BM36: =DATEDIF(AW36,BK36, "M")+1 -> 25 | BN36: =DATEDIF(AX36,BK36, "M")+1 -> 17 | BP36: 1 | BQ36: 0 | BR36: 12 | BS36: 1 | BT36: 0 | BU36: 1 | BV36: 0 | BW36: GW, 2016 | BX36: 0 | CC36: No | CF36: 2 | CG36: 3 | CI36: WT
A37: 38 | B37: C2/013 | C37: Abiodun | D37: Olufunke | E37: Oluwatoba | F37: Female | G37: 2 | H37: Nigeria | I37: University of Ibadan | J37: Environmental Sciences | L37: University of Ibadan | M37: Yes | P37: Married | Q37: Married | R37: ooluwatoba@cartafrica.org | S37: oluwatobang@yahoo.com | T37: +2348023451103 | U37: M.Sc. Cellular Parasitology, M.Sc Epidemiology | V37: 26284 | W37: Impact of environmental pollution on the prevalence of soil transmitted helminthes infection among primary school children in Ibadan | X37: Field | Y37: No | Z37: Primary | AA37: 17 | AB37: 40920 | AC37: 40969 | AE37: Dr. Roseangela Nwuba | AH37: =COUNTA(AE37:AG37) -> 1 | AI37: Home | AL37: Yes | AO37: Academic | AQ37: Lecturer | AT37: University of Ibadan | AU37: 0000-0003-1781-2550 | AW37: 40969 | AX37: 41214 | AY37: Yes | BD37: 41852 | BE37: Yes | BF37: 42064 | BG37: Yes | BK37: 43787 | BL37: Completed | BM37: =DATEDIF(AW37,BK37, "M")+1 -> 93 | BN37: =DATEDIF(AX37,BK37, "M")+1 -> 85 | BP37: 4 | BQ37: 0 | BR37: 0 | BS37: 0 | BT37: 0 | BU37: 0 | BV37: 0 | BW37: No | BX37: 0 | CC37: No | CF37: 3 | CG37: 3 | CI37: NF | CJ37: Deceased 10/02/2023
A38: 39 | B38: C2/014 | C38: Peter | D38: Mpasho | E38: Mwamtobe | F38: Male | G38: 2 | H38: Malawi | I38: University of Malawi | J38: Disease Epidemiology | K38: MATHEMATICS AND STATISTICS | L38: University of the Malawi | M38: Yes | P38: married | Q38: Married | R38: pmwamtobe@cartafrica.org | S38: pmwamtobe@gmail.com, pmwamtobe@poly.ac.mw | T38: 265999458069/265888626168 | U38: MSc in Mathematical Epidemiology (online) | V38: 27826 | W38: Optimal (control of) intervention strategies for malaria – TB co-infection | X38: Clinical research | Y38: yes | Z38: Primary | AA38: 8 | AB38: 41186 | AC38: 40969 | AE38: Prof. Ebrahim Momoniat | AF38: Prof. Shirley Abelman | AG38: Prof. Jean M. Tchuenche | AH38: =COUNTA(AE38:AG38) -> 3 | AI38: Other | AJ38: Other | AK38: Other | AL38: No | AM38: No | AN38: No | AO38: Academic | AP38: Lecturer | AQ38: Lecturer | AR38: No | AS38: Senior Lecturer, Head of Applied Studies Dept | AT38: UNIVERSITY OF MALAWI | AU38: 0000-0003-1861-3377 | AW38: 40969 | AX38: 41214 | AY38: Yes | BD38: 41852 | BE38: Yes | BF38: 42064 | BG38: Yes | BK38: 42064 | BL38: Completed | BM38: =DATEDIF(AW38,BK38, "M")+1 -> 37 | BN38: =DATEDIF(AX38,BK38, "M")+1 -> 29 | BP38: 0 | BQ38: 2 | BR38: 6 | BS38: 1 | BT38: 0 | BU38: 1 | BV38: 0 | BW38: No | BX38: 0 | CC38: No | CF38: 5 | CG38: 6 | CI38: NF
A39: 40 | B39: C2/015 | C39: Siphesihle | D39: Primrose Theodora | E39: Mtshali | F39: Female | G39: 2 | H39: South Africa | I39: University of the Witwatersrand | J39: Kinesiology | K39: Department of Physiotherapy | L39: University of the Witwatersrand | M39: Yes | P39: NF | R39: pmtshali@cartafrica.org | S39: Siphe.mtshali@wits.ac.za | T39: +27723106078 | U39: M.Sc Physiotherapy | V39: 27470 | W39: Impact of an education programme on coaches’ knowledge, attitudes and practices on injury prevention amongst football players. | X39: Field | Y39: No | Z39: Primary | AA39: 15.5 | AB39: 40952 | AC39: 40969 | AD39: 45741 | AE39: Prof. Mbambo-Kekana Nonceba Priscilla | AF39: Dr. Hellen Myezwa | AG39: Dr. Kerith Aginsky | AH39: =COUNTA(AE39:AG39) -> 3 | AI39: Other | AJ39: Home | AK39: Home/ Host | AL39: Yes | AM39: Yes | AN39: Yes | AO39: Academic | AP39: Lecturer | AT39: NF | AU39: 0000-0002-8343-0342 | AW39: 40969 | AX39: 41214 | AY39: Yes | BD39: 41852 | BE39: Yes | BF39: 42064 | BG39: Yes | BL39: Terminated | BP39: 1 | BQ39: 0 | BR39: 0 | BS39: 0 | BT39: 0 | BU39: 0 | BV39: 0 | BW39: No | BX39: 0 | CC39: No | CF39: 1 | CG39: NF | CI39: NF
A40: 41 | B40: C2/016 | C40: Nalugo | D40: Scovia | E40: Mbalinda | F40: Female | G40: 2 | H40: Uganda | I40: Makerere University | J40: Epidemiology | K40: Dept of Nursing | L40: Makerere University | M40: Yes | O40: Married | P40: Married | Q40: Married | R40: smbalinda@cartafrica.org | S40: snmbalinda@gmail.com, snmbalinda@chs.mak.ac.ug | T40: +256782212151 | U40: MSc. Population and Reproductive Health (online) | V40: 28657 | W40: Assessment of rural Ugandan HIV+ young adults women’s reproductive needs and rights to design a positive prevention service framework | X40: Field | Y40: No | Z40: Primary | AA40: 29 | AB40: 40867 | AC40: 40969 | AE40: Dr. Daniel Kabonge Kaye | AF40: Dr. Noah Kiwanuka | AG40: Prof. Fred Wabwire-Mangen | AH40: =COUNTA(AE40:AG40) -> 3 | AI40: Home | AJ40: Home | AK40: Home/ Host | AL40: Yes | AM40: No | AN40: No | AO40: Academic | AP40: Lecturer | AQ40: Lecturer | AR40: No | AT40: Makerere Univeristy | AU40: 0000-0002-4945-130X | AW40: 40969 | AX40: 41214 | AY40: Yes | BD40: 41852 | BE40: Yes | BF40: 42064 | BG40: Yes | BK40: 43108 | BL40: Completed | BM40: =DATEDIF(AW40,BK40, "M")+1 -> 71 | BN40: =DATEDIF(AX40,BK40, "M")+1 -> 63 | BP40: 6 | BQ40: 20 | BR40: 18 | BS40: 5 | BT40: 0 | BU40: 0 | BV40: 0 | BW40: JAS 2, 2012 | BX40: 0 | CC40: No | CF40: 3 | CG40: 3 | CI40: NF
...

Sheet Terminations
A1: No. | B1: Name | C1: Institution | D1: Gender | E1: Cohort | F1: Suspension | G1: Date of Termination | H1: Year | I1: Reason for Termination | J1: Detailed reason for termination
A2: 1 | B2: Stephen Pentz | C2: University of Witwatersrand | D2: Male | E2: 3 | G2: 2014 | H2: 2014 | I2: Lack of progress on milestone
A3: 2 | B3: Humphrey Phanuel Shao | C3: Ifakara Health Institute | D3: Male | E3: 3 | G3: 2016 | H3: 2016 | I3: Lack of progress on milestone
A4: 3 | B4: Peter Mwamba | C4: University of Nairobi | D4: Male | E4: 1 | F4: Yes | G4: 42583 | H4: 2016 | I4: Lack of progress on milestone
A5: 4 | B5: Gloria Omosa | C5: University of Nairobi | D5: Female | E5: 2 | F5: Aug 29 2014 | G5: October 2016 | H5: 2016 | I5: Failure to meet key milestone
A6: 5 | B6: Gad Rutayisire | C6: University of Rwanda | D6: Male | E6: 7 | F6: Nov 2 2017 | G6: 2017 | H6: 2017 | I6: Lack of progress on milestone
A7: 6 | B7: Gift Khangamwa | C7: University of Malawi | D7: Male | E7: 5 | F7: June 5 2017 | G7: 2017 | H7: 2017 | I7: Master Degree not recognised
A8: 7 | B8: Callen Onyambu | C8: University of Nairobi | D8: Female | E8: 5 | F8: June 5 2017 | G8: 2018 | H8: 2018 | I8: Lack of progress on milestone
A9: 8 | B9: Edwin Sang | C9: Moi University | D9: Male | E9: 6 | G9: 2018 | H9: 2018 | I9: Lack of progress on milestone
A10: 9 | B10: Hussein Masoud | C10: University of Dar es Salaam | D10: Male | E10: 5 | F10: yes | G10: 2018 | H10: 2018 | I10: Lack of progress on milestone
A11: 10 | B11: Teresa Kinyari | C11: University of Nairobi | D11: Female | E11: 1 | F11: Nov 18 2011 | G11: Not indicated | I11: Lack of progress on milestone
A12: 11 | B12: Jacqueline Mgumia | C12: University of Dar es Salaam | D12: Female | E12: 1 | F12: Feb 8 2012 | G12: Not indicated | I12: Lack of progress on milestone
A13: 12 | B13: Lackson Tembo | C13: University of Malawi | D13: Male | E13: 4 | G13: 43867 | H13: 2020 | I13: Lack of progress on milestone
A14: 13 | B14: Doris Kwesiga | C14: Makerere University | D14: Female | E14: 8 | G14: 43867 | H14: 2020 | I14: Inability to attend JAS 2 twice | J14: Unable to attend JAS 2 in South Africa due to her visa issues
A15: 14 | B15: Raymond Odokonyero | C15: Makerere University | D15: Male | E15: 5 | G15: 43930 | H15: 2020 | I15: Lack of progress on milestone
